2018-12-28 08:46:59,270 ERROR No module named 'deprecated'
Traceback (most recent call last):
  File "/Users/feifei/workspace/VirtualJudge/venv/lib/python3.7/site-packages/spider/core.py", line 23, in build_oj
    module_meta = __import__(f'spider.platforms.{str(name).lower()}', globals(), locals(), [name])
  File "/Users/feifei/workspace/VirtualJudge/venv/lib/python3.7/site-packages/spider/platforms/codeforces.py", line 9, in <module>
    from deprecated import deprecated
ModuleNotFoundError: No module named 'deprecated'
2018-12-28 08:53:15,631 ERROR HTTPConnectionPool(host='codeforces.com', port=80): Max retries exceeded with url: /problemset/problem/86/A (Caused by ConnectTimeoutError(<urllib3.connection.HTTPConnection object at 0x11326dfd0>, 'Connection to codeforces.com timed out. (connect timeout=7)'))
Traceback (most recent call last):
  File "/Users/feifei/workspace/VirtualJudge/venv/lib/python3.7/site-packages/urllib3/connection.py", line 159, in _new_conn
    (self._dns_host, self.port), self.timeout, **extra_kw)
  File "/Users/feifei/workspace/VirtualJudge/venv/lib/python3.7/site-packages/urllib3/util/connection.py", line 80, in create_connection
    raise err
  File "/Users/feifei/workspace/VirtualJudge/venv/lib/python3.7/site-packages/urllib3/util/connection.py", line 70, in create_connection
    sock.connect(sa)
socket.timeout: timed out

During handling of the above exception, another exception occurred:

Traceback (most recent call last):
  File "/Users/feifei/workspace/VirtualJudge/venv/lib/python3.7/site-packages/urllib3/connectionpool.py", line 600, in urlopen
    chunked=chunked)
  File "/Users/feifei/workspace/VirtualJudge/venv/lib/python3.7/site-packages/urllib3/connectionpool.py", line 354, in _make_request
    conn.request(method, url, **httplib_request_kw)
  File "/usr/local/Cellar/python/3.7.0/Frameworks/Python.framework/Versions/3.7/lib/python3.7/http/client.py", line 1229, in request
    self._send_request(method, url, body, headers, encode_chunked)
  File "/usr/local/Cellar/python/3.7.0/Frameworks/Python.framework/Versions/3.7/lib/python3.7/http/client.py", line 1275, in _send_request
    self.endheaders(body, encode_chunked=encode_chunked)
  File "/usr/local/Cellar/python/3.7.0/Frameworks/Python.framework/Versions/3.7/lib/python3.7/http/client.py", line 1224, in endheaders
    self._send_output(message_body, encode_chunked=encode_chunked)
  File "/usr/local/Cellar/python/3.7.0/Frameworks/Python.framework/Versions/3.7/lib/python3.7/http/client.py", line 1016, in _send_output
    self.send(msg)
  File "/usr/local/Cellar/python/3.7.0/Frameworks/Python.framework/Versions/3.7/lib/python3.7/http/client.py", line 956, in send
    self.connect()
  File "/Users/feifei/workspace/VirtualJudge/venv/lib/python3.7/site-packages/urllib3/connection.py", line 181, in connect
    conn = self._new_conn()
  File "/Users/feifei/workspace/VirtualJudge/venv/lib/python3.7/site-packages/urllib3/connection.py", line 164, in _new_conn
    (self.host, self.timeout))
urllib3.exceptions.ConnectTimeoutError: (<urllib3.connection.HTTPConnection object at 0x11326dfd0>, 'Connection to codeforces.com timed out. (connect timeout=7)')

During handling of the above exception, another exception occurred:

Traceback (most recent call last):
  File "/Users/feifei/workspace/VirtualJudge/venv/lib/python3.7/site-packages/requests/adapters.py", line 449, in send
    timeout=timeout
  File "/Users/feifei/workspace/VirtualJudge/venv/lib/python3.7/site-packages/urllib3/connectionpool.py", line 638, in urlopen
    _stacktrace=sys.exc_info()[2])
  File "/Users/feifei/workspace/VirtualJudge/venv/lib/python3.7/site-packages/urllib3/util/retry.py", line 398, in increment
    raise MaxRetryError(_pool, url, error or ResponseError(cause))
urllib3.exceptions.MaxRetryError: HTTPConnectionPool(host='codeforces.com', port=80): Max retries exceeded with url: /problemset/problem/86/A (Caused by ConnectTimeoutError(<urllib3.connection.HTTPConnection object at 0x11326dfd0>, 'Connection to codeforces.com timed out. (connect timeout=7)'))

During handling of the above exception, another exception occurred:

Traceback (most recent call last):
  File "/Users/feifei/workspace/VirtualJudge/venv/lib/python3.7/site-packages/spider/utils.py", line 48, in get
    self._response = self._request.get(url, timeout=self._timeout, proxies=self._proxies, **kwargs)
  File "/Users/feifei/workspace/VirtualJudge/venv/lib/python3.7/site-packages/requests/sessions.py", line 537, in get
    return self.request('GET', url, **kwargs)
  File "/Users/feifei/workspace/VirtualJudge/venv/lib/python3.7/site-packages/requests/sessions.py", line 524, in request
    resp = self.send(prep, **send_kwargs)
  File "/Users/feifei/workspace/VirtualJudge/venv/lib/python3.7/site-packages/raven/breadcrumbs.py", line 341, in send
    resp = real_send(self, request, *args, **kwargs)
  File "/Users/feifei/workspace/VirtualJudge/venv/lib/python3.7/site-packages/requests/sessions.py", line 637, in send
    r = adapter.send(request, **kwargs)
  File "/Users/feifei/workspace/VirtualJudge/venv/lib/python3.7/site-packages/requests/adapters.py", line 504, in send
    raise ConnectTimeout(e, request=request)
requests.exceptions.ConnectTimeout: HTTPConnectionPool(host='codeforces.com', port=80): Max retries exceeded with url: /problemset/problem/86/A (Caused by ConnectTimeoutError(<urllib3.connection.HTTPConnection object at 0x11326dfd0>, 'Connection to codeforces.com timed out. (connect timeout=7)'))
2018-12-28 09:46:10,688 ERROR HTTPConnectionPool(host='codeforces.com', port=80): Max retries exceeded with url: / (Caused by ConnectTimeoutError(<urllib3.connection.HTTPConnection object at 0x106e57a20>, 'Connection to codeforces.com timed out. (connect timeout=7)'))
Traceback (most recent call last):
  File "/Users/feifei/workspace/VirtualJudge/venv/lib/python3.7/site-packages/urllib3/connection.py", line 159, in _new_conn
    (self._dns_host, self.port), self.timeout, **extra_kw)
  File "/Users/feifei/workspace/VirtualJudge/venv/lib/python3.7/site-packages/urllib3/util/connection.py", line 80, in create_connection
    raise err
  File "/Users/feifei/workspace/VirtualJudge/venv/lib/python3.7/site-packages/urllib3/util/connection.py", line 70, in create_connection
    sock.connect(sa)
socket.timeout: timed out

During handling of the above exception, another exception occurred:

Traceback (most recent call last):
  File "/Users/feifei/workspace/VirtualJudge/venv/lib/python3.7/site-packages/urllib3/connectionpool.py", line 600, in urlopen
    chunked=chunked)
  File "/Users/feifei/workspace/VirtualJudge/venv/lib/python3.7/site-packages/urllib3/connectionpool.py", line 354, in _make_request
    conn.request(method, url, **httplib_request_kw)
  File "/usr/local/Cellar/python/3.7.0/Frameworks/Python.framework/Versions/3.7/lib/python3.7/http/client.py", line 1229, in request
    self._send_request(method, url, body, headers, encode_chunked)
  File "/usr/local/Cellar/python/3.7.0/Frameworks/Python.framework/Versions/3.7/lib/python3.7/http/client.py", line 1275, in _send_request
    self.endheaders(body, encode_chunked=encode_chunked)
  File "/usr/local/Cellar/python/3.7.0/Frameworks/Python.framework/Versions/3.7/lib/python3.7/http/client.py", line 1224, in endheaders
    self._send_output(message_body, encode_chunked=encode_chunked)
  File "/usr/local/Cellar/python/3.7.0/Frameworks/Python.framework/Versions/3.7/lib/python3.7/http/client.py", line 1016, in _send_output
    self.send(msg)
  File "/usr/local/Cellar/python/3.7.0/Frameworks/Python.framework/Versions/3.7/lib/python3.7/http/client.py", line 956, in send
    self.connect()
  File "/Users/feifei/workspace/VirtualJudge/venv/lib/python3.7/site-packages/urllib3/connection.py", line 181, in connect
    conn = self._new_conn()
  File "/Users/feifei/workspace/VirtualJudge/venv/lib/python3.7/site-packages/urllib3/connection.py", line 164, in _new_conn
    (self.host, self.timeout))
urllib3.exceptions.ConnectTimeoutError: (<urllib3.connection.HTTPConnection object at 0x106e57a20>, 'Connection to codeforces.com timed out. (connect timeout=7)')

During handling of the above exception, another exception occurred:

Traceback (most recent call last):
  File "/Users/feifei/workspace/VirtualJudge/venv/lib/python3.7/site-packages/requests/adapters.py", line 449, in send
    timeout=timeout
  File "/Users/feifei/workspace/VirtualJudge/venv/lib/python3.7/site-packages/urllib3/connectionpool.py", line 638, in urlopen
    _stacktrace=sys.exc_info()[2])
  File "/Users/feifei/workspace/VirtualJudge/venv/lib/python3.7/site-packages/urllib3/util/retry.py", line 398, in increment
    raise MaxRetryError(_pool, url, error or ResponseError(cause))
urllib3.exceptions.MaxRetryError: HTTPConnectionPool(host='codeforces.com', port=80): Max retries exceeded with url: / (Caused by ConnectTimeoutError(<urllib3.connection.HTTPConnection object at 0x106e57a20>, 'Connection to codeforces.com timed out. (connect timeout=7)'))

During handling of the above exception, another exception occurred:

Traceback (most recent call last):
  File "/Users/feifei/workspace/VirtualJudge/venv/lib/python3.7/site-packages/spider-1.0-py3.7.egg/spider/utils.py", line 48, in get
    self._response = self._request.get(url, timeout=self._timeout, proxies=self._proxies, **kwargs)
  File "/Users/feifei/workspace/VirtualJudge/venv/lib/python3.7/site-packages/requests/sessions.py", line 537, in get
    return self.request('GET', url, **kwargs)
  File "/Users/feifei/workspace/VirtualJudge/venv/lib/python3.7/site-packages/requests/sessions.py", line 524, in request
    resp = self.send(prep, **send_kwargs)
  File "/Users/feifei/workspace/VirtualJudge/venv/lib/python3.7/site-packages/raven/breadcrumbs.py", line 341, in send
    resp = real_send(self, request, *args, **kwargs)
  File "/Users/feifei/workspace/VirtualJudge/venv/lib/python3.7/site-packages/requests/sessions.py", line 637, in send
    r = adapter.send(request, **kwargs)
  File "/Users/feifei/workspace/VirtualJudge/venv/lib/python3.7/site-packages/requests/adapters.py", line 504, in send
    raise ConnectTimeout(e, request=request)
requests.exceptions.ConnectTimeout: HTTPConnectionPool(host='codeforces.com', port=80): Max retries exceeded with url: / (Caused by ConnectTimeoutError(<urllib3.connection.HTTPConnection object at 0x106e57a20>, 'Connection to codeforces.com timed out. (connect timeout=7)'))
2018-12-28 09:49:22,632 ERROR HTTPConnectionPool(host='codeforces.com', port=80): Max retries exceeded with url: / (Caused by ConnectTimeoutError(<urllib3.connection.HTTPConnection object at 0x10d8dcf60>, 'Connection to codeforces.com timed out. (connect timeout=7)'))
Traceback (most recent call last):
  File "/Users/feifei/workspace/VirtualJudge/venv/lib/python3.7/site-packages/urllib3/connection.py", line 159, in _new_conn
    (self._dns_host, self.port), self.timeout, **extra_kw)
  File "/Users/feifei/workspace/VirtualJudge/venv/lib/python3.7/site-packages/urllib3/util/connection.py", line 80, in create_connection
    raise err
  File "/Users/feifei/workspace/VirtualJudge/venv/lib/python3.7/site-packages/urllib3/util/connection.py", line 70, in create_connection
    sock.connect(sa)
socket.timeout: timed out

During handling of the above exception, another exception occurred:

Traceback (most recent call last):
  File "/Users/feifei/workspace/VirtualJudge/venv/lib/python3.7/site-packages/urllib3/connectionpool.py", line 600, in urlopen
    chunked=chunked)
  File "/Users/feifei/workspace/VirtualJudge/venv/lib/python3.7/site-packages/urllib3/connectionpool.py", line 354, in _make_request
    conn.request(method, url, **httplib_request_kw)
  File "/usr/local/Cellar/python/3.7.0/Frameworks/Python.framework/Versions/3.7/lib/python3.7/http/client.py", line 1229, in request
    self._send_request(method, url, body, headers, encode_chunked)
  File "/usr/local/Cellar/python/3.7.0/Frameworks/Python.framework/Versions/3.7/lib/python3.7/http/client.py", line 1275, in _send_request
    self.endheaders(body, encode_chunked=encode_chunked)
  File "/usr/local/Cellar/python/3.7.0/Frameworks/Python.framework/Versions/3.7/lib/python3.7/http/client.py", line 1224, in endheaders
    self._send_output(message_body, encode_chunked=encode_chunked)
  File "/usr/local/Cellar/python/3.7.0/Frameworks/Python.framework/Versions/3.7/lib/python3.7/http/client.py", line 1016, in _send_output
    self.send(msg)
  File "/usr/local/Cellar/python/3.7.0/Frameworks/Python.framework/Versions/3.7/lib/python3.7/http/client.py", line 956, in send
    self.connect()
  File "/Users/feifei/workspace/VirtualJudge/venv/lib/python3.7/site-packages/urllib3/connection.py", line 181, in connect
    conn = self._new_conn()
  File "/Users/feifei/workspace/VirtualJudge/venv/lib/python3.7/site-packages/urllib3/connection.py", line 164, in _new_conn
    (self.host, self.timeout))
urllib3.exceptions.ConnectTimeoutError: (<urllib3.connection.HTTPConnection object at 0x10d8dcf60>, 'Connection to codeforces.com timed out. (connect timeout=7)')

During handling of the above exception, another exception occurred:

Traceback (most recent call last):
  File "/Users/feifei/workspace/VirtualJudge/venv/lib/python3.7/site-packages/requests/adapters.py", line 449, in send
    timeout=timeout
  File "/Users/feifei/workspace/VirtualJudge/venv/lib/python3.7/site-packages/urllib3/connectionpool.py", line 638, in urlopen
    _stacktrace=sys.exc_info()[2])
  File "/Users/feifei/workspace/VirtualJudge/venv/lib/python3.7/site-packages/urllib3/util/retry.py", line 398, in increment
    raise MaxRetryError(_pool, url, error or ResponseError(cause))
urllib3.exceptions.MaxRetryError: HTTPConnectionPool(host='codeforces.com', port=80): Max retries exceeded with url: / (Caused by ConnectTimeoutError(<urllib3.connection.HTTPConnection object at 0x10d8dcf60>, 'Connection to codeforces.com timed out. (connect timeout=7)'))

During handling of the above exception, another exception occurred:

Traceback (most recent call last):
  File "/Users/feifei/workspace/VirtualJudge/venv/lib/python3.7/site-packages/spider-1.0-py3.7.egg/spider/utils.py", line 48, in get
    self._response = self._request.get(url, timeout=self._timeout, proxies=self._proxies, **kwargs)
  File "/Users/feifei/workspace/VirtualJudge/venv/lib/python3.7/site-packages/requests/sessions.py", line 537, in get
    return self.request('GET', url, **kwargs)
  File "/Users/feifei/workspace/VirtualJudge/venv/lib/python3.7/site-packages/requests/sessions.py", line 524, in request
    resp = self.send(prep, **send_kwargs)
  File "/Users/feifei/workspace/VirtualJudge/venv/lib/python3.7/site-packages/raven/breadcrumbs.py", line 341, in send
    resp = real_send(self, request, *args, **kwargs)
  File "/Users/feifei/workspace/VirtualJudge/venv/lib/python3.7/site-packages/requests/sessions.py", line 637, in send
    r = adapter.send(request, **kwargs)
  File "/Users/feifei/workspace/VirtualJudge/venv/lib/python3.7/site-packages/requests/adapters.py", line 504, in send
    raise ConnectTimeout(e, request=request)
requests.exceptions.ConnectTimeout: HTTPConnectionPool(host='codeforces.com', port=80): Max retries exceeded with url: / (Caused by ConnectTimeoutError(<urllib3.connection.HTTPConnection object at 0x10d8dcf60>, 'Connection to codeforces.com timed out. (connect timeout=7)'))
2018-12-28 09:49:29,652 ERROR HTTPConnectionPool(host='codeforces.com', port=80): Max retries exceeded with url: /enter?back=%2F (Caused by ConnectTimeoutError(<urllib3.connection.HTTPConnection object at 0x10dd34cf8>, 'Connection to codeforces.com timed out. (connect timeout=7)'))
Traceback (most recent call last):
  File "/Users/feifei/workspace/VirtualJudge/venv/lib/python3.7/site-packages/urllib3/connection.py", line 159, in _new_conn
    (self._dns_host, self.port), self.timeout, **extra_kw)
  File "/Users/feifei/workspace/VirtualJudge/venv/lib/python3.7/site-packages/urllib3/util/connection.py", line 80, in create_connection
    raise err
  File "/Users/feifei/workspace/VirtualJudge/venv/lib/python3.7/site-packages/urllib3/util/connection.py", line 70, in create_connection
    sock.connect(sa)
socket.timeout: timed out

During handling of the above exception, another exception occurred:

Traceback (most recent call last):
  File "/Users/feifei/workspace/VirtualJudge/venv/lib/python3.7/site-packages/urllib3/connectionpool.py", line 600, in urlopen
    chunked=chunked)
  File "/Users/feifei/workspace/VirtualJudge/venv/lib/python3.7/site-packages/urllib3/connectionpool.py", line 354, in _make_request
    conn.request(method, url, **httplib_request_kw)
  File "/usr/local/Cellar/python/3.7.0/Frameworks/Python.framework/Versions/3.7/lib/python3.7/http/client.py", line 1229, in request
    self._send_request(method, url, body, headers, encode_chunked)
  File "/usr/local/Cellar/python/3.7.0/Frameworks/Python.framework/Versions/3.7/lib/python3.7/http/client.py", line 1275, in _send_request
    self.endheaders(body, encode_chunked=encode_chunked)
  File "/usr/local/Cellar/python/3.7.0/Frameworks/Python.framework/Versions/3.7/lib/python3.7/http/client.py", line 1224, in endheaders
    self._send_output(message_body, encode_chunked=encode_chunked)
  File "/usr/local/Cellar/python/3.7.0/Frameworks/Python.framework/Versions/3.7/lib/python3.7/http/client.py", line 1016, in _send_output
    self.send(msg)
  File "/usr/local/Cellar/python/3.7.0/Frameworks/Python.framework/Versions/3.7/lib/python3.7/http/client.py", line 956, in send
    self.connect()
  File "/Users/feifei/workspace/VirtualJudge/venv/lib/python3.7/site-packages/urllib3/connection.py", line 181, in connect
    conn = self._new_conn()
  File "/Users/feifei/workspace/VirtualJudge/venv/lib/python3.7/site-packages/urllib3/connection.py", line 164, in _new_conn
    (self.host, self.timeout))
urllib3.exceptions.ConnectTimeoutError: (<urllib3.connection.HTTPConnection object at 0x10dd34cf8>, 'Connection to codeforces.com timed out. (connect timeout=7)')

During handling of the above exception, another exception occurred:

Traceback (most recent call last):
  File "/Users/feifei/workspace/VirtualJudge/venv/lib/python3.7/site-packages/requests/adapters.py", line 449, in send
    timeout=timeout
  File "/Users/feifei/workspace/VirtualJudge/venv/lib/python3.7/site-packages/urllib3/connectionpool.py", line 638, in urlopen
    _stacktrace=sys.exc_info()[2])
  File "/Users/feifei/workspace/VirtualJudge/venv/lib/python3.7/site-packages/urllib3/util/retry.py", line 398, in increment
    raise MaxRetryError(_pool, url, error or ResponseError(cause))
urllib3.exceptions.MaxRetryError: HTTPConnectionPool(host='codeforces.com', port=80): Max retries exceeded with url: /enter?back=%2F (Caused by ConnectTimeoutError(<urllib3.connection.HTTPConnection object at 0x10dd34cf8>, 'Connection to codeforces.com timed out. (connect timeout=7)'))

During handling of the above exception, another exception occurred:

Traceback (most recent call last):
  File "/Users/feifei/workspace/VirtualJudge/venv/lib/python3.7/site-packages/spider-1.0-py3.7.egg/spider/utils.py", line 48, in get
    self._response = self._request.get(url, timeout=self._timeout, proxies=self._proxies, **kwargs)
  File "/Users/feifei/workspace/VirtualJudge/venv/lib/python3.7/site-packages/requests/sessions.py", line 537, in get
    return self.request('GET', url, **kwargs)
  File "/Users/feifei/workspace/VirtualJudge/venv/lib/python3.7/site-packages/requests/sessions.py", line 524, in request
    resp = self.send(prep, **send_kwargs)
  File "/Users/feifei/workspace/VirtualJudge/venv/lib/python3.7/site-packages/raven/breadcrumbs.py", line 341, in send
    resp = real_send(self, request, *args, **kwargs)
  File "/Users/feifei/workspace/VirtualJudge/venv/lib/python3.7/site-packages/requests/sessions.py", line 637, in send
    r = adapter.send(request, **kwargs)
  File "/Users/feifei/workspace/VirtualJudge/venv/lib/python3.7/site-packages/requests/adapters.py", line 504, in send
    raise ConnectTimeout(e, request=request)
requests.exceptions.ConnectTimeout: HTTPConnectionPool(host='codeforces.com', port=80): Max retries exceeded with url: /enter?back=%2F (Caused by ConnectTimeoutError(<urllib3.connection.HTTPConnection object at 0x10dd34cf8>, 'Connection to codeforces.com timed out. (connect timeout=7)'))
2018-12-28 09:49:29,655 ERROR 'NoneType' object has no attribute 'text'
Traceback (most recent call last):
  File "/Users/feifei/workspace/VirtualJudge/venv/lib/python3.7/site-packages/spider-1.0-py3.7.egg/spider/platforms/codeforces.py", line 136, in login_website
    soup = BeautifulSoup(res.text, 'lxml')
AttributeError: 'NoneType' object has no attribute 'text'
2018-12-28 09:49:36,663 ERROR HTTPConnectionPool(host='codeforces.com', port=80): Max retries exceeded with url: / (Caused by ConnectTimeoutError(<urllib3.connection.HTTPConnection object at 0x10de86400>, 'Connection to codeforces.com timed out. (connect timeout=7)'))
Traceback (most recent call last):
  File "/Users/feifei/workspace/VirtualJudge/venv/lib/python3.7/site-packages/urllib3/connection.py", line 159, in _new_conn
    (self._dns_host, self.port), self.timeout, **extra_kw)
  File "/Users/feifei/workspace/VirtualJudge/venv/lib/python3.7/site-packages/urllib3/util/connection.py", line 80, in create_connection
    raise err
  File "/Users/feifei/workspace/VirtualJudge/venv/lib/python3.7/site-packages/urllib3/util/connection.py", line 70, in create_connection
    sock.connect(sa)
socket.timeout: timed out

During handling of the above exception, another exception occurred:

Traceback (most recent call last):
  File "/Users/feifei/workspace/VirtualJudge/venv/lib/python3.7/site-packages/urllib3/connectionpool.py", line 600, in urlopen
    chunked=chunked)
  File "/Users/feifei/workspace/VirtualJudge/venv/lib/python3.7/site-packages/urllib3/connectionpool.py", line 354, in _make_request
    conn.request(method, url, **httplib_request_kw)
  File "/usr/local/Cellar/python/3.7.0/Frameworks/Python.framework/Versions/3.7/lib/python3.7/http/client.py", line 1229, in request
    self._send_request(method, url, body, headers, encode_chunked)
  File "/usr/local/Cellar/python/3.7.0/Frameworks/Python.framework/Versions/3.7/lib/python3.7/http/client.py", line 1275, in _send_request
    self.endheaders(body, encode_chunked=encode_chunked)
  File "/usr/local/Cellar/python/3.7.0/Frameworks/Python.framework/Versions/3.7/lib/python3.7/http/client.py", line 1224, in endheaders
    self._send_output(message_body, encode_chunked=encode_chunked)
  File "/usr/local/Cellar/python/3.7.0/Frameworks/Python.framework/Versions/3.7/lib/python3.7/http/client.py", line 1016, in _send_output
    self.send(msg)
  File "/usr/local/Cellar/python/3.7.0/Frameworks/Python.framework/Versions/3.7/lib/python3.7/http/client.py", line 956, in send
    self.connect()
  File "/Users/feifei/workspace/VirtualJudge/venv/lib/python3.7/site-packages/urllib3/connection.py", line 181, in connect
    conn = self._new_conn()
  File "/Users/feifei/workspace/VirtualJudge/venv/lib/python3.7/site-packages/urllib3/connection.py", line 164, in _new_conn
    (self.host, self.timeout))
urllib3.exceptions.ConnectTimeoutError: (<urllib3.connection.HTTPConnection object at 0x10de86400>, 'Connection to codeforces.com timed out. (connect timeout=7)')

During handling of the above exception, another exception occurred:

Traceback (most recent call last):
  File "/Users/feifei/workspace/VirtualJudge/venv/lib/python3.7/site-packages/requests/adapters.py", line 449, in send
    timeout=timeout
  File "/Users/feifei/workspace/VirtualJudge/venv/lib/python3.7/site-packages/urllib3/connectionpool.py", line 638, in urlopen
    _stacktrace=sys.exc_info()[2])
  File "/Users/feifei/workspace/VirtualJudge/venv/lib/python3.7/site-packages/urllib3/util/retry.py", line 398, in increment
    raise MaxRetryError(_pool, url, error or ResponseError(cause))
urllib3.exceptions.MaxRetryError: HTTPConnectionPool(host='codeforces.com', port=80): Max retries exceeded with url: / (Caused by ConnectTimeoutError(<urllib3.connection.HTTPConnection object at 0x10de86400>, 'Connection to codeforces.com timed out. (connect timeout=7)'))

During handling of the above exception, another exception occurred:

Traceback (most recent call last):
  File "/Users/feifei/workspace/VirtualJudge/venv/lib/python3.7/site-packages/spider-1.0-py3.7.egg/spider/utils.py", line 48, in get
    self._response = self._request.get(url, timeout=self._timeout, proxies=self._proxies, **kwargs)
  File "/Users/feifei/workspace/VirtualJudge/venv/lib/python3.7/site-packages/requests/sessions.py", line 537, in get
    return self.request('GET', url, **kwargs)
  File "/Users/feifei/workspace/VirtualJudge/venv/lib/python3.7/site-packages/requests/sessions.py", line 524, in request
    resp = self.send(prep, **send_kwargs)
  File "/Users/feifei/workspace/VirtualJudge/venv/lib/python3.7/site-packages/raven/breadcrumbs.py", line 341, in send
    resp = real_send(self, request, *args, **kwargs)
  File "/Users/feifei/workspace/VirtualJudge/venv/lib/python3.7/site-packages/requests/sessions.py", line 637, in send
    r = adapter.send(request, **kwargs)
  File "/Users/feifei/workspace/VirtualJudge/venv/lib/python3.7/site-packages/requests/adapters.py", line 504, in send
    raise ConnectTimeout(e, request=request)
requests.exceptions.ConnectTimeout: HTTPConnectionPool(host='codeforces.com', port=80): Max retries exceeded with url: / (Caused by ConnectTimeoutError(<urllib3.connection.HTTPConnection object at 0x10de86400>, 'Connection to codeforces.com timed out. (connect timeout=7)'))
2018-12-28 09:49:57,407 ERROR HTTPConnectionPool(host='codeforces.com', port=80): Read timed out.
Traceback (most recent call last):
  File "/Users/feifei/workspace/VirtualJudge/venv/lib/python3.7/site-packages/urllib3/response.py", line 360, in _error_catcher
    yield
  File "/Users/feifei/workspace/VirtualJudge/venv/lib/python3.7/site-packages/urllib3/response.py", line 669, in read_chunked
    chunk = self._handle_chunk(amt)
  File "/Users/feifei/workspace/VirtualJudge/venv/lib/python3.7/site-packages/urllib3/response.py", line 624, in _handle_chunk
    returned_chunk = self._fp._safe_read(self.chunk_left)
  File "/usr/local/Cellar/python/3.7.0/Frameworks/Python.framework/Versions/3.7/lib/python3.7/http/client.py", line 610, in _safe_read
    chunk = self.fp.read(min(amt, MAXAMOUNT))
  File "/usr/local/Cellar/python/3.7.0/Frameworks/Python.framework/Versions/3.7/lib/python3.7/socket.py", line 589, in readinto
    return self._sock.recv_into(b)
socket.timeout: timed out

During handling of the above exception, another exception occurred:

Traceback (most recent call last):
  File "/Users/feifei/workspace/VirtualJudge/venv/lib/python3.7/site-packages/requests/models.py", line 750, in generate
    for chunk in self.raw.stream(chunk_size, decode_content=True):
  File "/Users/feifei/workspace/VirtualJudge/venv/lib/python3.7/site-packages/urllib3/response.py", line 490, in stream
    for line in self.read_chunked(amt, decode_content=decode_content):
  File "/Users/feifei/workspace/VirtualJudge/venv/lib/python3.7/site-packages/urllib3/response.py", line 694, in read_chunked
    self._original_response.close()
  File "/usr/local/Cellar/python/3.7.0/Frameworks/Python.framework/Versions/3.7/lib/python3.7/contextlib.py", line 130, in __exit__
    self.gen.throw(type, value, traceback)
  File "/Users/feifei/workspace/VirtualJudge/venv/lib/python3.7/site-packages/urllib3/response.py", line 365, in _error_catcher
    raise ReadTimeoutError(self._pool, None, 'Read timed out.')
urllib3.exceptions.ReadTimeoutError: HTTPConnectionPool(host='codeforces.com', port=80): Read timed out.

During handling of the above exception, another exception occurred:

Traceback (most recent call last):
  File "/Users/feifei/workspace/VirtualJudge/venv/lib/python3.7/site-packages/spider-1.0-py3.7.egg/spider/utils.py", line 48, in get
    self._response = self._request.get(url, timeout=self._timeout, proxies=self._proxies, **kwargs)
  File "/Users/feifei/workspace/VirtualJudge/venv/lib/python3.7/site-packages/requests/sessions.py", line 537, in get
    return self.request('GET', url, **kwargs)
  File "/Users/feifei/workspace/VirtualJudge/venv/lib/python3.7/site-packages/requests/sessions.py", line 524, in request
    resp = self.send(prep, **send_kwargs)
  File "/Users/feifei/workspace/VirtualJudge/venv/lib/python3.7/site-packages/raven/breadcrumbs.py", line 341, in send
    resp = real_send(self, request, *args, **kwargs)
  File "/Users/feifei/workspace/VirtualJudge/venv/lib/python3.7/site-packages/requests/sessions.py", line 677, in send
    r.content
  File "/Users/feifei/workspace/VirtualJudge/venv/lib/python3.7/site-packages/requests/models.py", line 828, in content
    self._content = b''.join(self.iter_content(CONTENT_CHUNK_SIZE)) or b''
  File "/Users/feifei/workspace/VirtualJudge/venv/lib/python3.7/site-packages/requests/models.py", line 757, in generate
    raise ConnectionError(e)
requests.exceptions.ConnectionError: HTTPConnectionPool(host='codeforces.com', port=80): Read timed out.
2018-12-28 09:53:36,047 ERROR HTTPConnectionPool(host='codeforces.com', port=80): Max retries exceeded with url: / (Caused by ConnectTimeoutError(<urllib3.connection.HTTPConnection object at 0x10de9bcf8>, 'Connection to codeforces.com timed out. (connect timeout=7)'))
Traceback (most recent call last):
  File "/Users/feifei/workspace/VirtualJudge/venv/lib/python3.7/site-packages/urllib3/connection.py", line 159, in _new_conn
    (self._dns_host, self.port), self.timeout, **extra_kw)
  File "/Users/feifei/workspace/VirtualJudge/venv/lib/python3.7/site-packages/urllib3/util/connection.py", line 80, in create_connection
    raise err
  File "/Users/feifei/workspace/VirtualJudge/venv/lib/python3.7/site-packages/urllib3/util/connection.py", line 70, in create_connection
    sock.connect(sa)
socket.timeout: timed out

During handling of the above exception, another exception occurred:

Traceback (most recent call last):
  File "/Users/feifei/workspace/VirtualJudge/venv/lib/python3.7/site-packages/urllib3/connectionpool.py", line 600, in urlopen
    chunked=chunked)
  File "/Users/feifei/workspace/VirtualJudge/venv/lib/python3.7/site-packages/urllib3/connectionpool.py", line 354, in _make_request
    conn.request(method, url, **httplib_request_kw)
  File "/usr/local/Cellar/python/3.7.0/Frameworks/Python.framework/Versions/3.7/lib/python3.7/http/client.py", line 1229, in request
    self._send_request(method, url, body, headers, encode_chunked)
  File "/usr/local/Cellar/python/3.7.0/Frameworks/Python.framework/Versions/3.7/lib/python3.7/http/client.py", line 1275, in _send_request
    self.endheaders(body, encode_chunked=encode_chunked)
  File "/usr/local/Cellar/python/3.7.0/Frameworks/Python.framework/Versions/3.7/lib/python3.7/http/client.py", line 1224, in endheaders
    self._send_output(message_body, encode_chunked=encode_chunked)
  File "/usr/local/Cellar/python/3.7.0/Frameworks/Python.framework/Versions/3.7/lib/python3.7/http/client.py", line 1016, in _send_output
    self.send(msg)
  File "/usr/local/Cellar/python/3.7.0/Frameworks/Python.framework/Versions/3.7/lib/python3.7/http/client.py", line 956, in send
    self.connect()
  File "/Users/feifei/workspace/VirtualJudge/venv/lib/python3.7/site-packages/urllib3/connection.py", line 181, in connect
    conn = self._new_conn()
  File "/Users/feifei/workspace/VirtualJudge/venv/lib/python3.7/site-packages/urllib3/connection.py", line 164, in _new_conn
    (self.host, self.timeout))
urllib3.exceptions.ConnectTimeoutError: (<urllib3.connection.HTTPConnection object at 0x10de9bcf8>, 'Connection to codeforces.com timed out. (connect timeout=7)')

During handling of the above exception, another exception occurred:

Traceback (most recent call last):
  File "/Users/feifei/workspace/VirtualJudge/venv/lib/python3.7/site-packages/requests/adapters.py", line 449, in send
    timeout=timeout
  File "/Users/feifei/workspace/VirtualJudge/venv/lib/python3.7/site-packages/urllib3/connectionpool.py", line 638, in urlopen
    _stacktrace=sys.exc_info()[2])
  File "/Users/feifei/workspace/VirtualJudge/venv/lib/python3.7/site-packages/urllib3/util/retry.py", line 398, in increment
    raise MaxRetryError(_pool, url, error or ResponseError(cause))
urllib3.exceptions.MaxRetryError: HTTPConnectionPool(host='codeforces.com', port=80): Max retries exceeded with url: / (Caused by ConnectTimeoutError(<urllib3.connection.HTTPConnection object at 0x10de9bcf8>, 'Connection to codeforces.com timed out. (connect timeout=7)'))

During handling of the above exception, another exception occurred:

Traceback (most recent call last):
  File "/Users/feifei/workspace/VirtualJudge/venv/lib/python3.7/site-packages/spider-1.0-py3.7.egg/spider/utils.py", line 48, in get
    self._response = self._request.get(url, timeout=self._timeout, proxies=self._proxies, **kwargs)
  File "/Users/feifei/workspace/VirtualJudge/venv/lib/python3.7/site-packages/requests/sessions.py", line 537, in get
    return self.request('GET', url, **kwargs)
  File "/Users/feifei/workspace/VirtualJudge/venv/lib/python3.7/site-packages/requests/sessions.py", line 524, in request
    resp = self.send(prep, **send_kwargs)
  File "/Users/feifei/workspace/VirtualJudge/venv/lib/python3.7/site-packages/raven/breadcrumbs.py", line 341, in send
    resp = real_send(self, request, *args, **kwargs)
  File "/Users/feifei/workspace/VirtualJudge/venv/lib/python3.7/site-packages/requests/sessions.py", line 637, in send
    r = adapter.send(request, **kwargs)
  File "/Users/feifei/workspace/VirtualJudge/venv/lib/python3.7/site-packages/requests/adapters.py", line 504, in send
    raise ConnectTimeout(e, request=request)
requests.exceptions.ConnectTimeout: HTTPConnectionPool(host='codeforces.com', port=80): Max retries exceeded with url: / (Caused by ConnectTimeoutError(<urllib3.connection.HTTPConnection object at 0x10de9bcf8>, 'Connection to codeforces.com timed out. (connect timeout=7)'))
2018-12-28 09:53:43,056 ERROR HTTPConnectionPool(host='codeforces.com', port=80): Max retries exceeded with url: /enter?back=%2F (Caused by ConnectTimeoutError(<urllib3.connection.HTTPConnection object at 0x10dfb7e10>, 'Connection to codeforces.com timed out. (connect timeout=7)'))
Traceback (most recent call last):
  File "/Users/feifei/workspace/VirtualJudge/venv/lib/python3.7/site-packages/urllib3/connection.py", line 159, in _new_conn
    (self._dns_host, self.port), self.timeout, **extra_kw)
  File "/Users/feifei/workspace/VirtualJudge/venv/lib/python3.7/site-packages/urllib3/util/connection.py", line 80, in create_connection
    raise err
  File "/Users/feifei/workspace/VirtualJudge/venv/lib/python3.7/site-packages/urllib3/util/connection.py", line 70, in create_connection
    sock.connect(sa)
socket.timeout: timed out

During handling of the above exception, another exception occurred:

Traceback (most recent call last):
  File "/Users/feifei/workspace/VirtualJudge/venv/lib/python3.7/site-packages/urllib3/connectionpool.py", line 600, in urlopen
    chunked=chunked)
  File "/Users/feifei/workspace/VirtualJudge/venv/lib/python3.7/site-packages/urllib3/connectionpool.py", line 354, in _make_request
    conn.request(method, url, **httplib_request_kw)
  File "/usr/local/Cellar/python/3.7.0/Frameworks/Python.framework/Versions/3.7/lib/python3.7/http/client.py", line 1229, in request
    self._send_request(method, url, body, headers, encode_chunked)
  File "/usr/local/Cellar/python/3.7.0/Frameworks/Python.framework/Versions/3.7/lib/python3.7/http/client.py", line 1275, in _send_request
    self.endheaders(body, encode_chunked=encode_chunked)
  File "/usr/local/Cellar/python/3.7.0/Frameworks/Python.framework/Versions/3.7/lib/python3.7/http/client.py", line 1224, in endheaders
    self._send_output(message_body, encode_chunked=encode_chunked)
  File "/usr/local/Cellar/python/3.7.0/Frameworks/Python.framework/Versions/3.7/lib/python3.7/http/client.py", line 1016, in _send_output
    self.send(msg)
  File "/usr/local/Cellar/python/3.7.0/Frameworks/Python.framework/Versions/3.7/lib/python3.7/http/client.py", line 956, in send
    self.connect()
  File "/Users/feifei/workspace/VirtualJudge/venv/lib/python3.7/site-packages/urllib3/connection.py", line 181, in connect
    conn = self._new_conn()
  File "/Users/feifei/workspace/VirtualJudge/venv/lib/python3.7/site-packages/urllib3/connection.py", line 164, in _new_conn
    (self.host, self.timeout))
urllib3.exceptions.ConnectTimeoutError: (<urllib3.connection.HTTPConnection object at 0x10dfb7e10>, 'Connection to codeforces.com timed out. (connect timeout=7)')

During handling of the above exception, another exception occurred:

Traceback (most recent call last):
  File "/Users/feifei/workspace/VirtualJudge/venv/lib/python3.7/site-packages/requests/adapters.py", line 449, in send
    timeout=timeout
  File "/Users/feifei/workspace/VirtualJudge/venv/lib/python3.7/site-packages/urllib3/connectionpool.py", line 638, in urlopen
    _stacktrace=sys.exc_info()[2])
  File "/Users/feifei/workspace/VirtualJudge/venv/lib/python3.7/site-packages/urllib3/util/retry.py", line 398, in increment
    raise MaxRetryError(_pool, url, error or ResponseError(cause))
urllib3.exceptions.MaxRetryError: HTTPConnectionPool(host='codeforces.com', port=80): Max retries exceeded with url: /enter?back=%2F (Caused by ConnectTimeoutError(<urllib3.connection.HTTPConnection object at 0x10dfb7e10>, 'Connection to codeforces.com timed out. (connect timeout=7)'))

During handling of the above exception, another exception occurred:

Traceback (most recent call last):
  File "/Users/feifei/workspace/VirtualJudge/venv/lib/python3.7/site-packages/spider-1.0-py3.7.egg/spider/utils.py", line 48, in get
    self._response = self._request.get(url, timeout=self._timeout, proxies=self._proxies, **kwargs)
  File "/Users/feifei/workspace/VirtualJudge/venv/lib/python3.7/site-packages/requests/sessions.py", line 537, in get
    return self.request('GET', url, **kwargs)
  File "/Users/feifei/workspace/VirtualJudge/venv/lib/python3.7/site-packages/requests/sessions.py", line 524, in request
    resp = self.send(prep, **send_kwargs)
  File "/Users/feifei/workspace/VirtualJudge/venv/lib/python3.7/site-packages/raven/breadcrumbs.py", line 341, in send
    resp = real_send(self, request, *args, **kwargs)
  File "/Users/feifei/workspace/VirtualJudge/venv/lib/python3.7/site-packages/requests/sessions.py", line 637, in send
    r = adapter.send(request, **kwargs)
  File "/Users/feifei/workspace/VirtualJudge/venv/lib/python3.7/site-packages/requests/adapters.py", line 504, in send
    raise ConnectTimeout(e, request=request)
requests.exceptions.ConnectTimeout: HTTPConnectionPool(host='codeforces.com', port=80): Max retries exceeded with url: /enter?back=%2F (Caused by ConnectTimeoutError(<urllib3.connection.HTTPConnection object at 0x10dfb7e10>, 'Connection to codeforces.com timed out. (connect timeout=7)'))
2018-12-28 09:53:43,062 ERROR 'NoneType' object has no attribute 'text'
Traceback (most recent call last):
  File "/Users/feifei/workspace/VirtualJudge/venv/lib/python3.7/site-packages/spider-1.0-py3.7.egg/spider/platforms/codeforces.py", line 136, in login_website
    soup = BeautifulSoup(res.text, 'lxml')
AttributeError: 'NoneType' object has no attribute 'text'
2018-12-28 09:53:50,068 ERROR HTTPConnectionPool(host='codeforces.com', port=80): Max retries exceeded with url: / (Caused by ConnectTimeoutError(<urllib3.connection.HTTPConnection object at 0x10dfb7b38>, 'Connection to codeforces.com timed out. (connect timeout=7)'))
Traceback (most recent call last):
  File "/Users/feifei/workspace/VirtualJudge/venv/lib/python3.7/site-packages/urllib3/connection.py", line 159, in _new_conn
    (self._dns_host, self.port), self.timeout, **extra_kw)
  File "/Users/feifei/workspace/VirtualJudge/venv/lib/python3.7/site-packages/urllib3/util/connection.py", line 80, in create_connection
    raise err
  File "/Users/feifei/workspace/VirtualJudge/venv/lib/python3.7/site-packages/urllib3/util/connection.py", line 70, in create_connection
    sock.connect(sa)
socket.timeout: timed out

During handling of the above exception, another exception occurred:

Traceback (most recent call last):
  File "/Users/feifei/workspace/VirtualJudge/venv/lib/python3.7/site-packages/urllib3/connectionpool.py", line 600, in urlopen
    chunked=chunked)
  File "/Users/feifei/workspace/VirtualJudge/venv/lib/python3.7/site-packages/urllib3/connectionpool.py", line 354, in _make_request
    conn.request(method, url, **httplib_request_kw)
  File "/usr/local/Cellar/python/3.7.0/Frameworks/Python.framework/Versions/3.7/lib/python3.7/http/client.py", line 1229, in request
    self._send_request(method, url, body, headers, encode_chunked)
  File "/usr/local/Cellar/python/3.7.0/Frameworks/Python.framework/Versions/3.7/lib/python3.7/http/client.py", line 1275, in _send_request
    self.endheaders(body, encode_chunked=encode_chunked)
  File "/usr/local/Cellar/python/3.7.0/Frameworks/Python.framework/Versions/3.7/lib/python3.7/http/client.py", line 1224, in endheaders
    self._send_output(message_body, encode_chunked=encode_chunked)
  File "/usr/local/Cellar/python/3.7.0/Frameworks/Python.framework/Versions/3.7/lib/python3.7/http/client.py", line 1016, in _send_output
    self.send(msg)
  File "/usr/local/Cellar/python/3.7.0/Frameworks/Python.framework/Versions/3.7/lib/python3.7/http/client.py", line 956, in send
    self.connect()
  File "/Users/feifei/workspace/VirtualJudge/venv/lib/python3.7/site-packages/urllib3/connection.py", line 181, in connect
    conn = self._new_conn()
  File "/Users/feifei/workspace/VirtualJudge/venv/lib/python3.7/site-packages/urllib3/connection.py", line 164, in _new_conn
    (self.host, self.timeout))
urllib3.exceptions.ConnectTimeoutError: (<urllib3.connection.HTTPConnection object at 0x10dfb7b38>, 'Connection to codeforces.com timed out. (connect timeout=7)')

During handling of the above exception, another exception occurred:

Traceback (most recent call last):
  File "/Users/feifei/workspace/VirtualJudge/venv/lib/python3.7/site-packages/requests/adapters.py", line 449, in send
    timeout=timeout
  File "/Users/feifei/workspace/VirtualJudge/venv/lib/python3.7/site-packages/urllib3/connectionpool.py", line 638, in urlopen
    _stacktrace=sys.exc_info()[2])
  File "/Users/feifei/workspace/VirtualJudge/venv/lib/python3.7/site-packages/urllib3/util/retry.py", line 398, in increment
    raise MaxRetryError(_pool, url, error or ResponseError(cause))
urllib3.exceptions.MaxRetryError: HTTPConnectionPool(host='codeforces.com', port=80): Max retries exceeded with url: / (Caused by ConnectTimeoutError(<urllib3.connection.HTTPConnection object at 0x10dfb7b38>, 'Connection to codeforces.com timed out. (connect timeout=7)'))

During handling of the above exception, another exception occurred:

Traceback (most recent call last):
  File "/Users/feifei/workspace/VirtualJudge/venv/lib/python3.7/site-packages/spider-1.0-py3.7.egg/spider/utils.py", line 48, in get
    self._response = self._request.get(url, timeout=self._timeout, proxies=self._proxies, **kwargs)
  File "/Users/feifei/workspace/VirtualJudge/venv/lib/python3.7/site-packages/requests/sessions.py", line 537, in get
    return self.request('GET', url, **kwargs)
  File "/Users/feifei/workspace/VirtualJudge/venv/lib/python3.7/site-packages/requests/sessions.py", line 524, in request
    resp = self.send(prep, **send_kwargs)
  File "/Users/feifei/workspace/VirtualJudge/venv/lib/python3.7/site-packages/raven/breadcrumbs.py", line 341, in send
    resp = real_send(self, request, *args, **kwargs)
  File "/Users/feifei/workspace/VirtualJudge/venv/lib/python3.7/site-packages/requests/sessions.py", line 637, in send
    r = adapter.send(request, **kwargs)
  File "/Users/feifei/workspace/VirtualJudge/venv/lib/python3.7/site-packages/requests/adapters.py", line 504, in send
    raise ConnectTimeout(e, request=request)
requests.exceptions.ConnectTimeout: HTTPConnectionPool(host='codeforces.com', port=80): Max retries exceeded with url: / (Caused by ConnectTimeoutError(<urllib3.connection.HTTPConnection object at 0x10dfb7b38>, 'Connection to codeforces.com timed out. (connect timeout=7)'))
2018-12-28 09:53:59,089 ERROR HTTPConnectionPool(host='codeforces.com', port=80): Max retries exceeded with url: / (Caused by ConnectTimeoutError(<urllib3.connection.HTTPConnection object at 0x10e13ba90>, 'Connection to codeforces.com timed out. (connect timeout=7)'))
Traceback (most recent call last):
  File "/Users/feifei/workspace/VirtualJudge/venv/lib/python3.7/site-packages/urllib3/connection.py", line 159, in _new_conn
    (self._dns_host, self.port), self.timeout, **extra_kw)
  File "/Users/feifei/workspace/VirtualJudge/venv/lib/python3.7/site-packages/urllib3/util/connection.py", line 80, in create_connection
    raise err
  File "/Users/feifei/workspace/VirtualJudge/venv/lib/python3.7/site-packages/urllib3/util/connection.py", line 70, in create_connection
    sock.connect(sa)
socket.timeout: timed out

During handling of the above exception, another exception occurred:

Traceback (most recent call last):
  File "/Users/feifei/workspace/VirtualJudge/venv/lib/python3.7/site-packages/urllib3/connectionpool.py", line 600, in urlopen
    chunked=chunked)
  File "/Users/feifei/workspace/VirtualJudge/venv/lib/python3.7/site-packages/urllib3/connectionpool.py", line 354, in _make_request
    conn.request(method, url, **httplib_request_kw)
  File "/usr/local/Cellar/python/3.7.0/Frameworks/Python.framework/Versions/3.7/lib/python3.7/http/client.py", line 1229, in request
    self._send_request(method, url, body, headers, encode_chunked)
  File "/usr/local/Cellar/python/3.7.0/Frameworks/Python.framework/Versions/3.7/lib/python3.7/http/client.py", line 1275, in _send_request
    self.endheaders(body, encode_chunked=encode_chunked)
  File "/usr/local/Cellar/python/3.7.0/Frameworks/Python.framework/Versions/3.7/lib/python3.7/http/client.py", line 1224, in endheaders
    self._send_output(message_body, encode_chunked=encode_chunked)
  File "/usr/local/Cellar/python/3.7.0/Frameworks/Python.framework/Versions/3.7/lib/python3.7/http/client.py", line 1016, in _send_output
    self.send(msg)
  File "/usr/local/Cellar/python/3.7.0/Frameworks/Python.framework/Versions/3.7/lib/python3.7/http/client.py", line 956, in send
    self.connect()
  File "/Users/feifei/workspace/VirtualJudge/venv/lib/python3.7/site-packages/urllib3/connection.py", line 181, in connect
    conn = self._new_conn()
  File "/Users/feifei/workspace/VirtualJudge/venv/lib/python3.7/site-packages/urllib3/connection.py", line 164, in _new_conn
    (self.host, self.timeout))
urllib3.exceptions.ConnectTimeoutError: (<urllib3.connection.HTTPConnection object at 0x10e13ba90>, 'Connection to codeforces.com timed out. (connect timeout=7)')

During handling of the above exception, another exception occurred:

Traceback (most recent call last):
  File "/Users/feifei/workspace/VirtualJudge/venv/lib/python3.7/site-packages/requests/adapters.py", line 449, in send
    timeout=timeout
  File "/Users/feifei/workspace/VirtualJudge/venv/lib/python3.7/site-packages/urllib3/connectionpool.py", line 638, in urlopen
    _stacktrace=sys.exc_info()[2])
  File "/Users/feifei/workspace/VirtualJudge/venv/lib/python3.7/site-packages/urllib3/util/retry.py", line 398, in increment
    raise MaxRetryError(_pool, url, error or ResponseError(cause))
urllib3.exceptions.MaxRetryError: HTTPConnectionPool(host='codeforces.com', port=80): Max retries exceeded with url: / (Caused by ConnectTimeoutError(<urllib3.connection.HTTPConnection object at 0x10e13ba90>, 'Connection to codeforces.com timed out. (connect timeout=7)'))

During handling of the above exception, another exception occurred:

Traceback (most recent call last):
  File "/Users/feifei/workspace/VirtualJudge/venv/lib/python3.7/site-packages/spider-1.0-py3.7.egg/spider/utils.py", line 48, in get
    self._response = self._request.get(url, timeout=self._timeout, proxies=self._proxies, **kwargs)
  File "/Users/feifei/workspace/VirtualJudge/venv/lib/python3.7/site-packages/requests/sessions.py", line 537, in get
    return self.request('GET', url, **kwargs)
  File "/Users/feifei/workspace/VirtualJudge/venv/lib/python3.7/site-packages/requests/sessions.py", line 524, in request
    resp = self.send(prep, **send_kwargs)
  File "/Users/feifei/workspace/VirtualJudge/venv/lib/python3.7/site-packages/raven/breadcrumbs.py", line 341, in send
    resp = real_send(self, request, *args, **kwargs)
  File "/Users/feifei/workspace/VirtualJudge/venv/lib/python3.7/site-packages/requests/sessions.py", line 637, in send
    r = adapter.send(request, **kwargs)
  File "/Users/feifei/workspace/VirtualJudge/venv/lib/python3.7/site-packages/requests/adapters.py", line 504, in send
    raise ConnectTimeout(e, request=request)
requests.exceptions.ConnectTimeout: HTTPConnectionPool(host='codeforces.com', port=80): Max retries exceeded with url: / (Caused by ConnectTimeoutError(<urllib3.connection.HTTPConnection object at 0x10e13ba90>, 'Connection to codeforces.com timed out. (connect timeout=7)'))
2018-12-28 10:09:18,931 ERROR HTTPConnectionPool(host='acm.wust.edu.cn', port=80): Max retries exceeded with url: / (Caused by ConnectTimeoutError(<urllib3.connection.HTTPConnection object at 0x111375550>, 'Connection to acm.wust.edu.cn timed out. (connect timeout=7)'))
Traceback (most recent call last):
  File "/Users/feifei/workspace/VirtualJudge/venv/lib/python3.7/site-packages/urllib3/connection.py", line 159, in _new_conn
    (self._dns_host, self.port), self.timeout, **extra_kw)
  File "/Users/feifei/workspace/VirtualJudge/venv/lib/python3.7/site-packages/urllib3/util/connection.py", line 80, in create_connection
    raise err
  File "/Users/feifei/workspace/VirtualJudge/venv/lib/python3.7/site-packages/urllib3/util/connection.py", line 70, in create_connection
    sock.connect(sa)
socket.timeout: timed out

During handling of the above exception, another exception occurred:

Traceback (most recent call last):
  File "/Users/feifei/workspace/VirtualJudge/venv/lib/python3.7/site-packages/urllib3/connectionpool.py", line 600, in urlopen
    chunked=chunked)
  File "/Users/feifei/workspace/VirtualJudge/venv/lib/python3.7/site-packages/urllib3/connectionpool.py", line 354, in _make_request
    conn.request(method, url, **httplib_request_kw)
  File "/usr/local/Cellar/python/3.7.0/Frameworks/Python.framework/Versions/3.7/lib/python3.7/http/client.py", line 1229, in request
    self._send_request(method, url, body, headers, encode_chunked)
  File "/usr/local/Cellar/python/3.7.0/Frameworks/Python.framework/Versions/3.7/lib/python3.7/http/client.py", line 1275, in _send_request
    self.endheaders(body, encode_chunked=encode_chunked)
  File "/usr/local/Cellar/python/3.7.0/Frameworks/Python.framework/Versions/3.7/lib/python3.7/http/client.py", line 1224, in endheaders
    self._send_output(message_body, encode_chunked=encode_chunked)
  File "/usr/local/Cellar/python/3.7.0/Frameworks/Python.framework/Versions/3.7/lib/python3.7/http/client.py", line 1016, in _send_output
    self.send(msg)
  File "/usr/local/Cellar/python/3.7.0/Frameworks/Python.framework/Versions/3.7/lib/python3.7/http/client.py", line 956, in send
    self.connect()
  File "/Users/feifei/workspace/VirtualJudge/venv/lib/python3.7/site-packages/urllib3/connection.py", line 181, in connect
    conn = self._new_conn()
  File "/Users/feifei/workspace/VirtualJudge/venv/lib/python3.7/site-packages/urllib3/connection.py", line 164, in _new_conn
    (self.host, self.timeout))
urllib3.exceptions.ConnectTimeoutError: (<urllib3.connection.HTTPConnection object at 0x111375550>, 'Connection to acm.wust.edu.cn timed out. (connect timeout=7)')

During handling of the above exception, another exception occurred:

Traceback (most recent call last):
  File "/Users/feifei/workspace/VirtualJudge/venv/lib/python3.7/site-packages/requests/adapters.py", line 449, in send
    timeout=timeout
  File "/Users/feifei/workspace/VirtualJudge/venv/lib/python3.7/site-packages/urllib3/connectionpool.py", line 638, in urlopen
    _stacktrace=sys.exc_info()[2])
  File "/Users/feifei/workspace/VirtualJudge/venv/lib/python3.7/site-packages/urllib3/util/retry.py", line 398, in increment
    raise MaxRetryError(_pool, url, error or ResponseError(cause))
urllib3.exceptions.MaxRetryError: HTTPConnectionPool(host='acm.wust.edu.cn', port=80): Max retries exceeded with url: / (Caused by ConnectTimeoutError(<urllib3.connection.HTTPConnection object at 0x111375550>, 'Connection to acm.wust.edu.cn timed out. (connect timeout=7)'))

During handling of the above exception, another exception occurred:

Traceback (most recent call last):
  File "/Users/feifei/workspace/VirtualJudge/venv/lib/python3.7/site-packages/spider-1.0-py3.7.egg/spider/utils.py", line 48, in get
    self._response = self._request.get(url, timeout=self._timeout, proxies=self._proxies, **kwargs)
  File "/Users/feifei/workspace/VirtualJudge/venv/lib/python3.7/site-packages/requests/sessions.py", line 537, in get
    return self.request('GET', url, **kwargs)
  File "/Users/feifei/workspace/VirtualJudge/venv/lib/python3.7/site-packages/requests/sessions.py", line 524, in request
    resp = self.send(prep, **send_kwargs)
  File "/Users/feifei/workspace/VirtualJudge/venv/lib/python3.7/site-packages/raven/breadcrumbs.py", line 341, in send
    resp = real_send(self, request, *args, **kwargs)
  File "/Users/feifei/workspace/VirtualJudge/venv/lib/python3.7/site-packages/requests/sessions.py", line 637, in send
    r = adapter.send(request, **kwargs)
  File "/Users/feifei/workspace/VirtualJudge/venv/lib/python3.7/site-packages/requests/adapters.py", line 504, in send
    raise ConnectTimeout(e, request=request)
requests.exceptions.ConnectTimeout: HTTPConnectionPool(host='acm.wust.edu.cn', port=80): Max retries exceeded with url: / (Caused by ConnectTimeoutError(<urllib3.connection.HTTPConnection object at 0x111375550>, 'Connection to acm.wust.edu.cn timed out. (connect timeout=7)'))
2018-12-28 10:38:17,822 ERROR HTTPSConnectionPool(host='judgeapi.u-aizu.ac.jp', port=443): Max retries exceeded with url: /resources/descriptions/en/902B (Caused by ConnectTimeoutError(<urllib3.connection.VerifiedHTTPSConnection object at 0x108caad68>, 'Connection to judgeapi.u-aizu.ac.jp timed out. (connect timeout=7)'))
Traceback (most recent call last):
  File "/Users/feifei/workspace/VirtualJudge/venv/lib/python3.7/site-packages/urllib3/connection.py", line 159, in _new_conn
    (self._dns_host, self.port), self.timeout, **extra_kw)
  File "/Users/feifei/workspace/VirtualJudge/venv/lib/python3.7/site-packages/urllib3/util/connection.py", line 80, in create_connection
    raise err
  File "/Users/feifei/workspace/VirtualJudge/venv/lib/python3.7/site-packages/urllib3/util/connection.py", line 70, in create_connection
    sock.connect(sa)
socket.timeout: timed out

During handling of the above exception, another exception occurred:

Traceback (most recent call last):
  File "/Users/feifei/workspace/VirtualJudge/venv/lib/python3.7/site-packages/urllib3/connectionpool.py", line 600, in urlopen
    chunked=chunked)
  File "/Users/feifei/workspace/VirtualJudge/venv/lib/python3.7/site-packages/urllib3/connectionpool.py", line 343, in _make_request
    self._validate_conn(conn)
  File "/Users/feifei/workspace/VirtualJudge/venv/lib/python3.7/site-packages/urllib3/connectionpool.py", line 839, in _validate_conn
    conn.connect()
  File "/Users/feifei/workspace/VirtualJudge/venv/lib/python3.7/site-packages/urllib3/connection.py", line 301, in connect
    conn = self._new_conn()
  File "/Users/feifei/workspace/VirtualJudge/venv/lib/python3.7/site-packages/urllib3/connection.py", line 164, in _new_conn
    (self.host, self.timeout))
urllib3.exceptions.ConnectTimeoutError: (<urllib3.connection.VerifiedHTTPSConnection object at 0x108caad68>, 'Connection to judgeapi.u-aizu.ac.jp timed out. (connect timeout=7)')

During handling of the above exception, another exception occurred:

Traceback (most recent call last):
  File "/Users/feifei/workspace/VirtualJudge/venv/lib/python3.7/site-packages/requests/adapters.py", line 449, in send
    timeout=timeout
  File "/Users/feifei/workspace/VirtualJudge/venv/lib/python3.7/site-packages/urllib3/connectionpool.py", line 638, in urlopen
    _stacktrace=sys.exc_info()[2])
  File "/Users/feifei/workspace/VirtualJudge/venv/lib/python3.7/site-packages/urllib3/util/retry.py", line 398, in increment
    raise MaxRetryError(_pool, url, error or ResponseError(cause))
urllib3.exceptions.MaxRetryError: HTTPSConnectionPool(host='judgeapi.u-aizu.ac.jp', port=443): Max retries exceeded with url: /resources/descriptions/en/902B (Caused by ConnectTimeoutError(<urllib3.connection.VerifiedHTTPSConnection object at 0x108caad68>, 'Connection to judgeapi.u-aizu.ac.jp timed out. (connect timeout=7)'))

During handling of the above exception, another exception occurred:

Traceback (most recent call last):
  File "/Users/feifei/workspace/VirtualJudge/venv/lib/python3.7/site-packages/spider-1.0-py3.7.egg/spider/utils.py", line 48, in get
    self._response = self._request.get(url, timeout=self._timeout, proxies=self._proxies, **kwargs)
  File "/Users/feifei/workspace/VirtualJudge/venv/lib/python3.7/site-packages/requests/sessions.py", line 537, in get
    return self.request('GET', url, **kwargs)
  File "/Users/feifei/workspace/VirtualJudge/venv/lib/python3.7/site-packages/requests/sessions.py", line 524, in request
    resp = self.send(prep, **send_kwargs)
  File "/Users/feifei/workspace/VirtualJudge/venv/lib/python3.7/site-packages/raven/breadcrumbs.py", line 341, in send
    resp = real_send(self, request, *args, **kwargs)
  File "/Users/feifei/workspace/VirtualJudge/venv/lib/python3.7/site-packages/requests/sessions.py", line 637, in send
    r = adapter.send(request, **kwargs)
  File "/Users/feifei/workspace/VirtualJudge/venv/lib/python3.7/site-packages/requests/adapters.py", line 504, in send
    raise ConnectTimeout(e, request=request)
requests.exceptions.ConnectTimeout: HTTPSConnectionPool(host='judgeapi.u-aizu.ac.jp', port=443): Max retries exceeded with url: /resources/descriptions/en/902B (Caused by ConnectTimeoutError(<urllib3.connection.VerifiedHTTPSConnection object at 0x108caad68>, 'Connection to judgeapi.u-aizu.ac.jp timed out. (connect timeout=7)'))
2018-12-28 10:38:33,902 ERROR HTTPConnectionPool(host='codeforces.com', port=80): Max retries exceeded with url: /problemset/problem/902/B (Caused by ConnectTimeoutError(<urllib3.connection.HTTPConnection object at 0x108ba5b00>, 'Connection to codeforces.com timed out. (connect timeout=7)'))
Traceback (most recent call last):
  File "/Users/feifei/workspace/VirtualJudge/venv/lib/python3.7/site-packages/urllib3/connection.py", line 159, in _new_conn
    (self._dns_host, self.port), self.timeout, **extra_kw)
  File "/Users/feifei/workspace/VirtualJudge/venv/lib/python3.7/site-packages/urllib3/util/connection.py", line 80, in create_connection
    raise err
  File "/Users/feifei/workspace/VirtualJudge/venv/lib/python3.7/site-packages/urllib3/util/connection.py", line 70, in create_connection
    sock.connect(sa)
socket.timeout: timed out

During handling of the above exception, another exception occurred:

Traceback (most recent call last):
  File "/Users/feifei/workspace/VirtualJudge/venv/lib/python3.7/site-packages/urllib3/connectionpool.py", line 600, in urlopen
    chunked=chunked)
  File "/Users/feifei/workspace/VirtualJudge/venv/lib/python3.7/site-packages/urllib3/connectionpool.py", line 354, in _make_request
    conn.request(method, url, **httplib_request_kw)
  File "/usr/local/Cellar/python/3.7.0/Frameworks/Python.framework/Versions/3.7/lib/python3.7/http/client.py", line 1229, in request
    self._send_request(method, url, body, headers, encode_chunked)
  File "/usr/local/Cellar/python/3.7.0/Frameworks/Python.framework/Versions/3.7/lib/python3.7/http/client.py", line 1275, in _send_request
    self.endheaders(body, encode_chunked=encode_chunked)
  File "/usr/local/Cellar/python/3.7.0/Frameworks/Python.framework/Versions/3.7/lib/python3.7/http/client.py", line 1224, in endheaders
    self._send_output(message_body, encode_chunked=encode_chunked)
  File "/usr/local/Cellar/python/3.7.0/Frameworks/Python.framework/Versions/3.7/lib/python3.7/http/client.py", line 1016, in _send_output
    self.send(msg)
  File "/usr/local/Cellar/python/3.7.0/Frameworks/Python.framework/Versions/3.7/lib/python3.7/http/client.py", line 956, in send
    self.connect()
  File "/Users/feifei/workspace/VirtualJudge/venv/lib/python3.7/site-packages/urllib3/connection.py", line 181, in connect
    conn = self._new_conn()
  File "/Users/feifei/workspace/VirtualJudge/venv/lib/python3.7/site-packages/urllib3/connection.py", line 164, in _new_conn
    (self.host, self.timeout))
urllib3.exceptions.ConnectTimeoutError: (<urllib3.connection.HTTPConnection object at 0x108ba5b00>, 'Connection to codeforces.com timed out. (connect timeout=7)')

During handling of the above exception, another exception occurred:

Traceback (most recent call last):
  File "/Users/feifei/workspace/VirtualJudge/venv/lib/python3.7/site-packages/requests/adapters.py", line 449, in send
    timeout=timeout
  File "/Users/feifei/workspace/VirtualJudge/venv/lib/python3.7/site-packages/urllib3/connectionpool.py", line 638, in urlopen
    _stacktrace=sys.exc_info()[2])
  File "/Users/feifei/workspace/VirtualJudge/venv/lib/python3.7/site-packages/urllib3/util/retry.py", line 398, in increment
    raise MaxRetryError(_pool, url, error or ResponseError(cause))
urllib3.exceptions.MaxRetryError: HTTPConnectionPool(host='codeforces.com', port=80): Max retries exceeded with url: /problemset/problem/902/B (Caused by ConnectTimeoutError(<urllib3.connection.HTTPConnection object at 0x108ba5b00>, 'Connection to codeforces.com timed out. (connect timeout=7)'))

During handling of the above exception, another exception occurred:

Traceback (most recent call last):
  File "/Users/feifei/workspace/VirtualJudge/venv/lib/python3.7/site-packages/spider-1.0-py3.7.egg/spider/utils.py", line 48, in get
    self._response = self._request.get(url, timeout=self._timeout, proxies=self._proxies, **kwargs)
  File "/Users/feifei/workspace/VirtualJudge/venv/lib/python3.7/site-packages/requests/sessions.py", line 537, in get
    return self.request('GET', url, **kwargs)
  File "/Users/feifei/workspace/VirtualJudge/venv/lib/python3.7/site-packages/requests/sessions.py", line 524, in request
    resp = self.send(prep, **send_kwargs)
  File "/Users/feifei/workspace/VirtualJudge/venv/lib/python3.7/site-packages/raven/breadcrumbs.py", line 341, in send
    resp = real_send(self, request, *args, **kwargs)
  File "/Users/feifei/workspace/VirtualJudge/venv/lib/python3.7/site-packages/requests/sessions.py", line 637, in send
    r = adapter.send(request, **kwargs)
  File "/Users/feifei/workspace/VirtualJudge/venv/lib/python3.7/site-packages/requests/adapters.py", line 504, in send
    raise ConnectTimeout(e, request=request)
requests.exceptions.ConnectTimeout: HTTPConnectionPool(host='codeforces.com', port=80): Max retries exceeded with url: /problemset/problem/902/B (Caused by ConnectTimeoutError(<urllib3.connection.HTTPConnection object at 0x108ba5b00>, 'Connection to codeforces.com timed out. (connect timeout=7)'))
2018-12-28 10:38:41,877 ERROR HTTPConnectionPool(host='codeforces.com', port=80): Max retries exceeded with url: /problemset/problem/902/B (Caused by ConnectTimeoutError(<urllib3.connection.HTTPConnection object at 0x10878b0b8>, 'Connection to codeforces.com timed out. (connect timeout=7)'))
Traceback (most recent call last):
  File "/Users/feifei/workspace/VirtualJudge/venv/lib/python3.7/site-packages/urllib3/connection.py", line 159, in _new_conn
    (self._dns_host, self.port), self.timeout, **extra_kw)
  File "/Users/feifei/workspace/VirtualJudge/venv/lib/python3.7/site-packages/urllib3/util/connection.py", line 80, in create_connection
    raise err
  File "/Users/feifei/workspace/VirtualJudge/venv/lib/python3.7/site-packages/urllib3/util/connection.py", line 70, in create_connection
    sock.connect(sa)
socket.timeout: timed out

During handling of the above exception, another exception occurred:

Traceback (most recent call last):
  File "/Users/feifei/workspace/VirtualJudge/venv/lib/python3.7/site-packages/urllib3/connectionpool.py", line 600, in urlopen
    chunked=chunked)
  File "/Users/feifei/workspace/VirtualJudge/venv/lib/python3.7/site-packages/urllib3/connectionpool.py", line 354, in _make_request
    conn.request(method, url, **httplib_request_kw)
  File "/usr/local/Cellar/python/3.7.0/Frameworks/Python.framework/Versions/3.7/lib/python3.7/http/client.py", line 1229, in request
    self._send_request(method, url, body, headers, encode_chunked)
  File "/usr/local/Cellar/python/3.7.0/Frameworks/Python.framework/Versions/3.7/lib/python3.7/http/client.py", line 1275, in _send_request
    self.endheaders(body, encode_chunked=encode_chunked)
  File "/usr/local/Cellar/python/3.7.0/Frameworks/Python.framework/Versions/3.7/lib/python3.7/http/client.py", line 1224, in endheaders
    self._send_output(message_body, encode_chunked=encode_chunked)
  File "/usr/local/Cellar/python/3.7.0/Frameworks/Python.framework/Versions/3.7/lib/python3.7/http/client.py", line 1016, in _send_output
    self.send(msg)
  File "/usr/local/Cellar/python/3.7.0/Frameworks/Python.framework/Versions/3.7/lib/python3.7/http/client.py", line 956, in send
    self.connect()
  File "/Users/feifei/workspace/VirtualJudge/venv/lib/python3.7/site-packages/urllib3/connection.py", line 181, in connect
    conn = self._new_conn()
  File "/Users/feifei/workspace/VirtualJudge/venv/lib/python3.7/site-packages/urllib3/connection.py", line 164, in _new_conn
    (self.host, self.timeout))
urllib3.exceptions.ConnectTimeoutError: (<urllib3.connection.HTTPConnection object at 0x10878b0b8>, 'Connection to codeforces.com timed out. (connect timeout=7)')

During handling of the above exception, another exception occurred:

Traceback (most recent call last):
  File "/Users/feifei/workspace/VirtualJudge/venv/lib/python3.7/site-packages/requests/adapters.py", line 449, in send
    timeout=timeout
  File "/Users/feifei/workspace/VirtualJudge/venv/lib/python3.7/site-packages/urllib3/connectionpool.py", line 638, in urlopen
    _stacktrace=sys.exc_info()[2])
  File "/Users/feifei/workspace/VirtualJudge/venv/lib/python3.7/site-packages/urllib3/util/retry.py", line 398, in increment
    raise MaxRetryError(_pool, url, error or ResponseError(cause))
urllib3.exceptions.MaxRetryError: HTTPConnectionPool(host='codeforces.com', port=80): Max retries exceeded with url: /problemset/problem/902/B (Caused by ConnectTimeoutError(<urllib3.connection.HTTPConnection object at 0x10878b0b8>, 'Connection to codeforces.com timed out. (connect timeout=7)'))

During handling of the above exception, another exception occurred:

Traceback (most recent call last):
  File "/Users/feifei/workspace/VirtualJudge/venv/lib/python3.7/site-packages/spider-1.0-py3.7.egg/spider/utils.py", line 48, in get
    self._response = self._request.get(url, timeout=self._timeout, proxies=self._proxies, **kwargs)
  File "/Users/feifei/workspace/VirtualJudge/venv/lib/python3.7/site-packages/requests/sessions.py", line 537, in get
    return self.request('GET', url, **kwargs)
  File "/Users/feifei/workspace/VirtualJudge/venv/lib/python3.7/site-packages/requests/sessions.py", line 524, in request
    resp = self.send(prep, **send_kwargs)
  File "/Users/feifei/workspace/VirtualJudge/venv/lib/python3.7/site-packages/raven/breadcrumbs.py", line 341, in send
    resp = real_send(self, request, *args, **kwargs)
  File "/Users/feifei/workspace/VirtualJudge/venv/lib/python3.7/site-packages/requests/sessions.py", line 637, in send
    r = adapter.send(request, **kwargs)
  File "/Users/feifei/workspace/VirtualJudge/venv/lib/python3.7/site-packages/requests/adapters.py", line 504, in send
    raise ConnectTimeout(e, request=request)
requests.exceptions.ConnectTimeout: HTTPConnectionPool(host='codeforces.com', port=80): Max retries exceeded with url: /problemset/problem/902/B (Caused by ConnectTimeoutError(<urllib3.connection.HTTPConnection object at 0x10878b0b8>, 'Connection to codeforces.com timed out. (connect timeout=7)'))
2018-12-28 10:38:49,812 ERROR HTTPConnectionPool(host='codeforces.com', port=80): Max retries exceeded with url: /problemset/problem/902/B (Caused by ConnectTimeoutError(<urllib3.connection.HTTPConnection object at 0x108caac88>, 'Connection to codeforces.com timed out. (connect timeout=7)'))
Traceback (most recent call last):
  File "/Users/feifei/workspace/VirtualJudge/venv/lib/python3.7/site-packages/urllib3/connection.py", line 159, in _new_conn
    (self._dns_host, self.port), self.timeout, **extra_kw)
  File "/Users/feifei/workspace/VirtualJudge/venv/lib/python3.7/site-packages/urllib3/util/connection.py", line 80, in create_connection
    raise err
  File "/Users/feifei/workspace/VirtualJudge/venv/lib/python3.7/site-packages/urllib3/util/connection.py", line 70, in create_connection
    sock.connect(sa)
socket.timeout: timed out

During handling of the above exception, another exception occurred:

Traceback (most recent call last):
  File "/Users/feifei/workspace/VirtualJudge/venv/lib/python3.7/site-packages/urllib3/connectionpool.py", line 600, in urlopen
    chunked=chunked)
  File "/Users/feifei/workspace/VirtualJudge/venv/lib/python3.7/site-packages/urllib3/connectionpool.py", line 354, in _make_request
    conn.request(method, url, **httplib_request_kw)
  File "/usr/local/Cellar/python/3.7.0/Frameworks/Python.framework/Versions/3.7/lib/python3.7/http/client.py", line 1229, in request
    self._send_request(method, url, body, headers, encode_chunked)
  File "/usr/local/Cellar/python/3.7.0/Frameworks/Python.framework/Versions/3.7/lib/python3.7/http/client.py", line 1275, in _send_request
    self.endheaders(body, encode_chunked=encode_chunked)
  File "/usr/local/Cellar/python/3.7.0/Frameworks/Python.framework/Versions/3.7/lib/python3.7/http/client.py", line 1224, in endheaders
    self._send_output(message_body, encode_chunked=encode_chunked)
  File "/usr/local/Cellar/python/3.7.0/Frameworks/Python.framework/Versions/3.7/lib/python3.7/http/client.py", line 1016, in _send_output
    self.send(msg)
  File "/usr/local/Cellar/python/3.7.0/Frameworks/Python.framework/Versions/3.7/lib/python3.7/http/client.py", line 956, in send
    self.connect()
  File "/Users/feifei/workspace/VirtualJudge/venv/lib/python3.7/site-packages/urllib3/connection.py", line 181, in connect
    conn = self._new_conn()
  File "/Users/feifei/workspace/VirtualJudge/venv/lib/python3.7/site-packages/urllib3/connection.py", line 164, in _new_conn
    (self.host, self.timeout))
urllib3.exceptions.ConnectTimeoutError: (<urllib3.connection.HTTPConnection object at 0x108caac88>, 'Connection to codeforces.com timed out. (connect timeout=7)')

During handling of the above exception, another exception occurred:

Traceback (most recent call last):
  File "/Users/feifei/workspace/VirtualJudge/venv/lib/python3.7/site-packages/requests/adapters.py", line 449, in send
    timeout=timeout
  File "/Users/feifei/workspace/VirtualJudge/venv/lib/python3.7/site-packages/urllib3/connectionpool.py", line 638, in urlopen
    _stacktrace=sys.exc_info()[2])
  File "/Users/feifei/workspace/VirtualJudge/venv/lib/python3.7/site-packages/urllib3/util/retry.py", line 398, in increment
    raise MaxRetryError(_pool, url, error or ResponseError(cause))
urllib3.exceptions.MaxRetryError: HTTPConnectionPool(host='codeforces.com', port=80): Max retries exceeded with url: /problemset/problem/902/B (Caused by ConnectTimeoutError(<urllib3.connection.HTTPConnection object at 0x108caac88>, 'Connection to codeforces.com timed out. (connect timeout=7)'))

During handling of the above exception, another exception occurred:

Traceback (most recent call last):
  File "/Users/feifei/workspace/VirtualJudge/venv/lib/python3.7/site-packages/spider-1.0-py3.7.egg/spider/utils.py", line 48, in get
    self._response = self._request.get(url, timeout=self._timeout, proxies=self._proxies, **kwargs)
  File "/Users/feifei/workspace/VirtualJudge/venv/lib/python3.7/site-packages/requests/sessions.py", line 537, in get
    return self.request('GET', url, **kwargs)
  File "/Users/feifei/workspace/VirtualJudge/venv/lib/python3.7/site-packages/requests/sessions.py", line 524, in request
    resp = self.send(prep, **send_kwargs)
  File "/Users/feifei/workspace/VirtualJudge/venv/lib/python3.7/site-packages/raven/breadcrumbs.py", line 341, in send
    resp = real_send(self, request, *args, **kwargs)
  File "/Users/feifei/workspace/VirtualJudge/venv/lib/python3.7/site-packages/requests/sessions.py", line 637, in send
    r = adapter.send(request, **kwargs)
  File "/Users/feifei/workspace/VirtualJudge/venv/lib/python3.7/site-packages/requests/adapters.py", line 504, in send
    raise ConnectTimeout(e, request=request)
requests.exceptions.ConnectTimeout: HTTPConnectionPool(host='codeforces.com', port=80): Max retries exceeded with url: /problemset/problem/902/B (Caused by ConnectTimeoutError(<urllib3.connection.HTTPConnection object at 0x108caac88>, 'Connection to codeforces.com timed out. (connect timeout=7)'))
2018-12-28 10:38:57,934 ERROR HTTPConnectionPool(host='codeforces.com', port=80): Max retries exceeded with url: /problemset/problem/902/B (Caused by ConnectTimeoutError(<urllib3.connection.HTTPConnection object at 0x108809be0>, 'Connection to codeforces.com timed out. (connect timeout=7)'))
Traceback (most recent call last):
  File "/Users/feifei/workspace/VirtualJudge/venv/lib/python3.7/site-packages/urllib3/connection.py", line 159, in _new_conn
    (self._dns_host, self.port), self.timeout, **extra_kw)
  File "/Users/feifei/workspace/VirtualJudge/venv/lib/python3.7/site-packages/urllib3/util/connection.py", line 80, in create_connection
    raise err
  File "/Users/feifei/workspace/VirtualJudge/venv/lib/python3.7/site-packages/urllib3/util/connection.py", line 70, in create_connection
    sock.connect(sa)
socket.timeout: timed out

During handling of the above exception, another exception occurred:

Traceback (most recent call last):
  File "/Users/feifei/workspace/VirtualJudge/venv/lib/python3.7/site-packages/urllib3/connectionpool.py", line 600, in urlopen
    chunked=chunked)
  File "/Users/feifei/workspace/VirtualJudge/venv/lib/python3.7/site-packages/urllib3/connectionpool.py", line 354, in _make_request
    conn.request(method, url, **httplib_request_kw)
  File "/usr/local/Cellar/python/3.7.0/Frameworks/Python.framework/Versions/3.7/lib/python3.7/http/client.py", line 1229, in request
    self._send_request(method, url, body, headers, encode_chunked)
  File "/usr/local/Cellar/python/3.7.0/Frameworks/Python.framework/Versions/3.7/lib/python3.7/http/client.py", line 1275, in _send_request
    self.endheaders(body, encode_chunked=encode_chunked)
  File "/usr/local/Cellar/python/3.7.0/Frameworks/Python.framework/Versions/3.7/lib/python3.7/http/client.py", line 1224, in endheaders
    self._send_output(message_body, encode_chunked=encode_chunked)
  File "/usr/local/Cellar/python/3.7.0/Frameworks/Python.framework/Versions/3.7/lib/python3.7/http/client.py", line 1016, in _send_output
    self.send(msg)
  File "/usr/local/Cellar/python/3.7.0/Frameworks/Python.framework/Versions/3.7/lib/python3.7/http/client.py", line 956, in send
    self.connect()
  File "/Users/feifei/workspace/VirtualJudge/venv/lib/python3.7/site-packages/urllib3/connection.py", line 181, in connect
    conn = self._new_conn()
  File "/Users/feifei/workspace/VirtualJudge/venv/lib/python3.7/site-packages/urllib3/connection.py", line 164, in _new_conn
    (self.host, self.timeout))
urllib3.exceptions.ConnectTimeoutError: (<urllib3.connection.HTTPConnection object at 0x108809be0>, 'Connection to codeforces.com timed out. (connect timeout=7)')

During handling of the above exception, another exception occurred:

Traceback (most recent call last):
  File "/Users/feifei/workspace/VirtualJudge/venv/lib/python3.7/site-packages/requests/adapters.py", line 449, in send
    timeout=timeout
  File "/Users/feifei/workspace/VirtualJudge/venv/lib/python3.7/site-packages/urllib3/connectionpool.py", line 638, in urlopen
    _stacktrace=sys.exc_info()[2])
  File "/Users/feifei/workspace/VirtualJudge/venv/lib/python3.7/site-packages/urllib3/util/retry.py", line 398, in increment
    raise MaxRetryError(_pool, url, error or ResponseError(cause))
urllib3.exceptions.MaxRetryError: HTTPConnectionPool(host='codeforces.com', port=80): Max retries exceeded with url: /problemset/problem/902/B (Caused by ConnectTimeoutError(<urllib3.connection.HTTPConnection object at 0x108809be0>, 'Connection to codeforces.com timed out. (connect timeout=7)'))

During handling of the above exception, another exception occurred:

Traceback (most recent call last):
  File "/Users/feifei/workspace/VirtualJudge/venv/lib/python3.7/site-packages/spider-1.0-py3.7.egg/spider/utils.py", line 48, in get
    self._response = self._request.get(url, timeout=self._timeout, proxies=self._proxies, **kwargs)
  File "/Users/feifei/workspace/VirtualJudge/venv/lib/python3.7/site-packages/requests/sessions.py", line 537, in get
    return self.request('GET', url, **kwargs)
  File "/Users/feifei/workspace/VirtualJudge/venv/lib/python3.7/site-packages/requests/sessions.py", line 524, in request
    resp = self.send(prep, **send_kwargs)
  File "/Users/feifei/workspace/VirtualJudge/venv/lib/python3.7/site-packages/raven/breadcrumbs.py", line 341, in send
    resp = real_send(self, request, *args, **kwargs)
  File "/Users/feifei/workspace/VirtualJudge/venv/lib/python3.7/site-packages/requests/sessions.py", line 637, in send
    r = adapter.send(request, **kwargs)
  File "/Users/feifei/workspace/VirtualJudge/venv/lib/python3.7/site-packages/requests/adapters.py", line 504, in send
    raise ConnectTimeout(e, request=request)
requests.exceptions.ConnectTimeout: HTTPConnectionPool(host='codeforces.com', port=80): Max retries exceeded with url: /problemset/problem/902/B (Caused by ConnectTimeoutError(<urllib3.connection.HTTPConnection object at 0x108809be0>, 'Connection to codeforces.com timed out. (connect timeout=7)'))
2018-12-28 10:39:10,946 ERROR HTTPConnectionPool(host='codeforces.com', port=80): Max retries exceeded with url: /problemset/problem/902/B (Caused by ConnectTimeoutError(<urllib3.connection.HTTPConnection object at 0x108ce1320>, 'Connection to codeforces.com timed out. (connect timeout=7)'))
Traceback (most recent call last):
  File "/Users/feifei/workspace/VirtualJudge/venv/lib/python3.7/site-packages/urllib3/connection.py", line 159, in _new_conn
    (self._dns_host, self.port), self.timeout, **extra_kw)
  File "/Users/feifei/workspace/VirtualJudge/venv/lib/python3.7/site-packages/urllib3/util/connection.py", line 80, in create_connection
    raise err
  File "/Users/feifei/workspace/VirtualJudge/venv/lib/python3.7/site-packages/urllib3/util/connection.py", line 70, in create_connection
    sock.connect(sa)
socket.timeout: timed out

During handling of the above exception, another exception occurred:

Traceback (most recent call last):
  File "/Users/feifei/workspace/VirtualJudge/venv/lib/python3.7/site-packages/urllib3/connectionpool.py", line 600, in urlopen
    chunked=chunked)
  File "/Users/feifei/workspace/VirtualJudge/venv/lib/python3.7/site-packages/urllib3/connectionpool.py", line 354, in _make_request
    conn.request(method, url, **httplib_request_kw)
  File "/usr/local/Cellar/python/3.7.0/Frameworks/Python.framework/Versions/3.7/lib/python3.7/http/client.py", line 1229, in request
    self._send_request(method, url, body, headers, encode_chunked)
  File "/usr/local/Cellar/python/3.7.0/Frameworks/Python.framework/Versions/3.7/lib/python3.7/http/client.py", line 1275, in _send_request
    self.endheaders(body, encode_chunked=encode_chunked)
  File "/usr/local/Cellar/python/3.7.0/Frameworks/Python.framework/Versions/3.7/lib/python3.7/http/client.py", line 1224, in endheaders
    self._send_output(message_body, encode_chunked=encode_chunked)
  File "/usr/local/Cellar/python/3.7.0/Frameworks/Python.framework/Versions/3.7/lib/python3.7/http/client.py", line 1016, in _send_output
    self.send(msg)
  File "/usr/local/Cellar/python/3.7.0/Frameworks/Python.framework/Versions/3.7/lib/python3.7/http/client.py", line 956, in send
    self.connect()
  File "/Users/feifei/workspace/VirtualJudge/venv/lib/python3.7/site-packages/urllib3/connection.py", line 181, in connect
    conn = self._new_conn()
  File "/Users/feifei/workspace/VirtualJudge/venv/lib/python3.7/site-packages/urllib3/connection.py", line 164, in _new_conn
    (self.host, self.timeout))
urllib3.exceptions.ConnectTimeoutError: (<urllib3.connection.HTTPConnection object at 0x108ce1320>, 'Connection to codeforces.com timed out. (connect timeout=7)')

During handling of the above exception, another exception occurred:

Traceback (most recent call last):
  File "/Users/feifei/workspace/VirtualJudge/venv/lib/python3.7/site-packages/requests/adapters.py", line 449, in send
    timeout=timeout
  File "/Users/feifei/workspace/VirtualJudge/venv/lib/python3.7/site-packages/urllib3/connectionpool.py", line 638, in urlopen
    _stacktrace=sys.exc_info()[2])
  File "/Users/feifei/workspace/VirtualJudge/venv/lib/python3.7/site-packages/urllib3/util/retry.py", line 398, in increment
    raise MaxRetryError(_pool, url, error or ResponseError(cause))
urllib3.exceptions.MaxRetryError: HTTPConnectionPool(host='codeforces.com', port=80): Max retries exceeded with url: /problemset/problem/902/B (Caused by ConnectTimeoutError(<urllib3.connection.HTTPConnection object at 0x108ce1320>, 'Connection to codeforces.com timed out. (connect timeout=7)'))

During handling of the above exception, another exception occurred:

Traceback (most recent call last):
  File "/Users/feifei/workspace/VirtualJudge/venv/lib/python3.7/site-packages/spider-1.0-py3.7.egg/spider/utils.py", line 48, in get
    self._response = self._request.get(url, timeout=self._timeout, proxies=self._proxies, **kwargs)
  File "/Users/feifei/workspace/VirtualJudge/venv/lib/python3.7/site-packages/requests/sessions.py", line 537, in get
    return self.request('GET', url, **kwargs)
  File "/Users/feifei/workspace/VirtualJudge/venv/lib/python3.7/site-packages/requests/sessions.py", line 524, in request
    resp = self.send(prep, **send_kwargs)
  File "/Users/feifei/workspace/VirtualJudge/venv/lib/python3.7/site-packages/raven/breadcrumbs.py", line 341, in send
    resp = real_send(self, request, *args, **kwargs)
  File "/Users/feifei/workspace/VirtualJudge/venv/lib/python3.7/site-packages/requests/sessions.py", line 637, in send
    r = adapter.send(request, **kwargs)
  File "/Users/feifei/workspace/VirtualJudge/venv/lib/python3.7/site-packages/requests/adapters.py", line 504, in send
    raise ConnectTimeout(e, request=request)
requests.exceptions.ConnectTimeout: HTTPConnectionPool(host='codeforces.com', port=80): Max retries exceeded with url: /problemset/problem/902/B (Caused by ConnectTimeoutError(<urllib3.connection.HTTPConnection object at 0x108ce1320>, 'Connection to codeforces.com timed out. (connect timeout=7)'))
2018-12-28 10:40:27,114 ERROR HTTPConnectionPool(host='codeforces.com', port=80): Max retries exceeded with url: / (Caused by ConnectTimeoutError(<urllib3.connection.HTTPConnection object at 0x1089f9f98>, 'Connection to codeforces.com timed out. (connect timeout=7)'))
Traceback (most recent call last):
  File "/Users/feifei/workspace/VirtualJudge/venv/lib/python3.7/site-packages/urllib3/connection.py", line 159, in _new_conn
    (self._dns_host, self.port), self.timeout, **extra_kw)
  File "/Users/feifei/workspace/VirtualJudge/venv/lib/python3.7/site-packages/urllib3/util/connection.py", line 80, in create_connection
    raise err
  File "/Users/feifei/workspace/VirtualJudge/venv/lib/python3.7/site-packages/urllib3/util/connection.py", line 70, in create_connection
    sock.connect(sa)
socket.timeout: timed out

During handling of the above exception, another exception occurred:

Traceback (most recent call last):
  File "/Users/feifei/workspace/VirtualJudge/venv/lib/python3.7/site-packages/urllib3/connectionpool.py", line 600, in urlopen
    chunked=chunked)
  File "/Users/feifei/workspace/VirtualJudge/venv/lib/python3.7/site-packages/urllib3/connectionpool.py", line 354, in _make_request
    conn.request(method, url, **httplib_request_kw)
  File "/usr/local/Cellar/python/3.7.0/Frameworks/Python.framework/Versions/3.7/lib/python3.7/http/client.py", line 1229, in request
    self._send_request(method, url, body, headers, encode_chunked)
  File "/usr/local/Cellar/python/3.7.0/Frameworks/Python.framework/Versions/3.7/lib/python3.7/http/client.py", line 1275, in _send_request
    self.endheaders(body, encode_chunked=encode_chunked)
  File "/usr/local/Cellar/python/3.7.0/Frameworks/Python.framework/Versions/3.7/lib/python3.7/http/client.py", line 1224, in endheaders
    self._send_output(message_body, encode_chunked=encode_chunked)
  File "/usr/local/Cellar/python/3.7.0/Frameworks/Python.framework/Versions/3.7/lib/python3.7/http/client.py", line 1016, in _send_output
    self.send(msg)
  File "/usr/local/Cellar/python/3.7.0/Frameworks/Python.framework/Versions/3.7/lib/python3.7/http/client.py", line 956, in send
    self.connect()
  File "/Users/feifei/workspace/VirtualJudge/venv/lib/python3.7/site-packages/urllib3/connection.py", line 181, in connect
    conn = self._new_conn()
  File "/Users/feifei/workspace/VirtualJudge/venv/lib/python3.7/site-packages/urllib3/connection.py", line 164, in _new_conn
    (self.host, self.timeout))
urllib3.exceptions.ConnectTimeoutError: (<urllib3.connection.HTTPConnection object at 0x1089f9f98>, 'Connection to codeforces.com timed out. (connect timeout=7)')

During handling of the above exception, another exception occurred:

Traceback (most recent call last):
  File "/Users/feifei/workspace/VirtualJudge/venv/lib/python3.7/site-packages/requests/adapters.py", line 449, in send
    timeout=timeout
  File "/Users/feifei/workspace/VirtualJudge/venv/lib/python3.7/site-packages/urllib3/connectionpool.py", line 638, in urlopen
    _stacktrace=sys.exc_info()[2])
  File "/Users/feifei/workspace/VirtualJudge/venv/lib/python3.7/site-packages/urllib3/util/retry.py", line 398, in increment
    raise MaxRetryError(_pool, url, error or ResponseError(cause))
urllib3.exceptions.MaxRetryError: HTTPConnectionPool(host='codeforces.com', port=80): Max retries exceeded with url: / (Caused by ConnectTimeoutError(<urllib3.connection.HTTPConnection object at 0x1089f9f98>, 'Connection to codeforces.com timed out. (connect timeout=7)'))

During handling of the above exception, another exception occurred:

Traceback (most recent call last):
  File "/Users/feifei/workspace/VirtualJudge/venv/lib/python3.7/site-packages/spider-1.0-py3.7.egg/spider/utils.py", line 48, in get
    self._response = self._request.get(url, timeout=self._timeout, proxies=self._proxies, **kwargs)
  File "/Users/feifei/workspace/VirtualJudge/venv/lib/python3.7/site-packages/requests/sessions.py", line 537, in get
    return self.request('GET', url, **kwargs)
  File "/Users/feifei/workspace/VirtualJudge/venv/lib/python3.7/site-packages/requests/sessions.py", line 524, in request
    resp = self.send(prep, **send_kwargs)
  File "/Users/feifei/workspace/VirtualJudge/venv/lib/python3.7/site-packages/raven/breadcrumbs.py", line 341, in send
    resp = real_send(self, request, *args, **kwargs)
  File "/Users/feifei/workspace/VirtualJudge/venv/lib/python3.7/site-packages/requests/sessions.py", line 637, in send
    r = adapter.send(request, **kwargs)
  File "/Users/feifei/workspace/VirtualJudge/venv/lib/python3.7/site-packages/requests/adapters.py", line 504, in send
    raise ConnectTimeout(e, request=request)
requests.exceptions.ConnectTimeout: HTTPConnectionPool(host='codeforces.com', port=80): Max retries exceeded with url: / (Caused by ConnectTimeoutError(<urllib3.connection.HTTPConnection object at 0x1089f9f98>, 'Connection to codeforces.com timed out. (connect timeout=7)'))
2018-12-28 10:40:34,122 ERROR HTTPConnectionPool(host='codeforces.com', port=80): Max retries exceeded with url: /enter?back=%2F (Caused by ConnectTimeoutError(<urllib3.connection.HTTPConnection object at 0x106418470>, 'Connection to codeforces.com timed out. (connect timeout=7)'))
Traceback (most recent call last):
  File "/Users/feifei/workspace/VirtualJudge/venv/lib/python3.7/site-packages/urllib3/connection.py", line 159, in _new_conn
    (self._dns_host, self.port), self.timeout, **extra_kw)
  File "/Users/feifei/workspace/VirtualJudge/venv/lib/python3.7/site-packages/urllib3/util/connection.py", line 80, in create_connection
    raise err
  File "/Users/feifei/workspace/VirtualJudge/venv/lib/python3.7/site-packages/urllib3/util/connection.py", line 70, in create_connection
    sock.connect(sa)
socket.timeout: timed out

During handling of the above exception, another exception occurred:

Traceback (most recent call last):
  File "/Users/feifei/workspace/VirtualJudge/venv/lib/python3.7/site-packages/urllib3/connectionpool.py", line 600, in urlopen
    chunked=chunked)
  File "/Users/feifei/workspace/VirtualJudge/venv/lib/python3.7/site-packages/urllib3/connectionpool.py", line 354, in _make_request
    conn.request(method, url, **httplib_request_kw)
  File "/usr/local/Cellar/python/3.7.0/Frameworks/Python.framework/Versions/3.7/lib/python3.7/http/client.py", line 1229, in request
    self._send_request(method, url, body, headers, encode_chunked)
  File "/usr/local/Cellar/python/3.7.0/Frameworks/Python.framework/Versions/3.7/lib/python3.7/http/client.py", line 1275, in _send_request
    self.endheaders(body, encode_chunked=encode_chunked)
  File "/usr/local/Cellar/python/3.7.0/Frameworks/Python.framework/Versions/3.7/lib/python3.7/http/client.py", line 1224, in endheaders
    self._send_output(message_body, encode_chunked=encode_chunked)
  File "/usr/local/Cellar/python/3.7.0/Frameworks/Python.framework/Versions/3.7/lib/python3.7/http/client.py", line 1016, in _send_output
    self.send(msg)
  File "/usr/local/Cellar/python/3.7.0/Frameworks/Python.framework/Versions/3.7/lib/python3.7/http/client.py", line 956, in send
    self.connect()
  File "/Users/feifei/workspace/VirtualJudge/venv/lib/python3.7/site-packages/urllib3/connection.py", line 181, in connect
    conn = self._new_conn()
  File "/Users/feifei/workspace/VirtualJudge/venv/lib/python3.7/site-packages/urllib3/connection.py", line 164, in _new_conn
    (self.host, self.timeout))
urllib3.exceptions.ConnectTimeoutError: (<urllib3.connection.HTTPConnection object at 0x106418470>, 'Connection to codeforces.com timed out. (connect timeout=7)')

During handling of the above exception, another exception occurred:

Traceback (most recent call last):
  File "/Users/feifei/workspace/VirtualJudge/venv/lib/python3.7/site-packages/requests/adapters.py", line 449, in send
    timeout=timeout
  File "/Users/feifei/workspace/VirtualJudge/venv/lib/python3.7/site-packages/urllib3/connectionpool.py", line 638, in urlopen
    _stacktrace=sys.exc_info()[2])
  File "/Users/feifei/workspace/VirtualJudge/venv/lib/python3.7/site-packages/urllib3/util/retry.py", line 398, in increment
    raise MaxRetryError(_pool, url, error or ResponseError(cause))
urllib3.exceptions.MaxRetryError: HTTPConnectionPool(host='codeforces.com', port=80): Max retries exceeded with url: /enter?back=%2F (Caused by ConnectTimeoutError(<urllib3.connection.HTTPConnection object at 0x106418470>, 'Connection to codeforces.com timed out. (connect timeout=7)'))

During handling of the above exception, another exception occurred:

Traceback (most recent call last):
  File "/Users/feifei/workspace/VirtualJudge/venv/lib/python3.7/site-packages/spider-1.0-py3.7.egg/spider/utils.py", line 48, in get
    self._response = self._request.get(url, timeout=self._timeout, proxies=self._proxies, **kwargs)
  File "/Users/feifei/workspace/VirtualJudge/venv/lib/python3.7/site-packages/requests/sessions.py", line 537, in get
    return self.request('GET', url, **kwargs)
  File "/Users/feifei/workspace/VirtualJudge/venv/lib/python3.7/site-packages/requests/sessions.py", line 524, in request
    resp = self.send(prep, **send_kwargs)
  File "/Users/feifei/workspace/VirtualJudge/venv/lib/python3.7/site-packages/raven/breadcrumbs.py", line 341, in send
    resp = real_send(self, request, *args, **kwargs)
  File "/Users/feifei/workspace/VirtualJudge/venv/lib/python3.7/site-packages/requests/sessions.py", line 637, in send
    r = adapter.send(request, **kwargs)
  File "/Users/feifei/workspace/VirtualJudge/venv/lib/python3.7/site-packages/requests/adapters.py", line 504, in send
    raise ConnectTimeout(e, request=request)
requests.exceptions.ConnectTimeout: HTTPConnectionPool(host='codeforces.com', port=80): Max retries exceeded with url: /enter?back=%2F (Caused by ConnectTimeoutError(<urllib3.connection.HTTPConnection object at 0x106418470>, 'Connection to codeforces.com timed out. (connect timeout=7)'))
2018-12-28 10:40:34,123 ERROR 'NoneType' object has no attribute 'text'
Traceback (most recent call last):
  File "/Users/feifei/workspace/VirtualJudge/venv/lib/python3.7/site-packages/spider-1.0-py3.7.egg/spider/platforms/codeforces.py", line 136, in login_website
    soup = BeautifulSoup(res.text, 'lxml')
AttributeError: 'NoneType' object has no attribute 'text'
2018-12-28 10:40:41,128 ERROR HTTPConnectionPool(host='codeforces.com', port=80): Max retries exceeded with url: / (Caused by ConnectTimeoutError(<urllib3.connection.HTTPConnection object at 0x106418b38>, 'Connection to codeforces.com timed out. (connect timeout=7)'))
Traceback (most recent call last):
  File "/Users/feifei/workspace/VirtualJudge/venv/lib/python3.7/site-packages/urllib3/connection.py", line 159, in _new_conn
    (self._dns_host, self.port), self.timeout, **extra_kw)
  File "/Users/feifei/workspace/VirtualJudge/venv/lib/python3.7/site-packages/urllib3/util/connection.py", line 80, in create_connection
    raise err
  File "/Users/feifei/workspace/VirtualJudge/venv/lib/python3.7/site-packages/urllib3/util/connection.py", line 70, in create_connection
    sock.connect(sa)
socket.timeout: timed out

During handling of the above exception, another exception occurred:

Traceback (most recent call last):
  File "/Users/feifei/workspace/VirtualJudge/venv/lib/python3.7/site-packages/urllib3/connectionpool.py", line 600, in urlopen
    chunked=chunked)
  File "/Users/feifei/workspace/VirtualJudge/venv/lib/python3.7/site-packages/urllib3/connectionpool.py", line 354, in _make_request
    conn.request(method, url, **httplib_request_kw)
  File "/usr/local/Cellar/python/3.7.0/Frameworks/Python.framework/Versions/3.7/lib/python3.7/http/client.py", line 1229, in request
    self._send_request(method, url, body, headers, encode_chunked)
  File "/usr/local/Cellar/python/3.7.0/Frameworks/Python.framework/Versions/3.7/lib/python3.7/http/client.py", line 1275, in _send_request
    self.endheaders(body, encode_chunked=encode_chunked)
  File "/usr/local/Cellar/python/3.7.0/Frameworks/Python.framework/Versions/3.7/lib/python3.7/http/client.py", line 1224, in endheaders
    self._send_output(message_body, encode_chunked=encode_chunked)
  File "/usr/local/Cellar/python/3.7.0/Frameworks/Python.framework/Versions/3.7/lib/python3.7/http/client.py", line 1016, in _send_output
    self.send(msg)
  File "/usr/local/Cellar/python/3.7.0/Frameworks/Python.framework/Versions/3.7/lib/python3.7/http/client.py", line 956, in send
    self.connect()
  File "/Users/feifei/workspace/VirtualJudge/venv/lib/python3.7/site-packages/urllib3/connection.py", line 181, in connect
    conn = self._new_conn()
  File "/Users/feifei/workspace/VirtualJudge/venv/lib/python3.7/site-packages/urllib3/connection.py", line 164, in _new_conn
    (self.host, self.timeout))
urllib3.exceptions.ConnectTimeoutError: (<urllib3.connection.HTTPConnection object at 0x106418b38>, 'Connection to codeforces.com timed out. (connect timeout=7)')

During handling of the above exception, another exception occurred:

Traceback (most recent call last):
  File "/Users/feifei/workspace/VirtualJudge/venv/lib/python3.7/site-packages/requests/adapters.py", line 449, in send
    timeout=timeout
  File "/Users/feifei/workspace/VirtualJudge/venv/lib/python3.7/site-packages/urllib3/connectionpool.py", line 638, in urlopen
    _stacktrace=sys.exc_info()[2])
  File "/Users/feifei/workspace/VirtualJudge/venv/lib/python3.7/site-packages/urllib3/util/retry.py", line 398, in increment
    raise MaxRetryError(_pool, url, error or ResponseError(cause))
urllib3.exceptions.MaxRetryError: HTTPConnectionPool(host='codeforces.com', port=80): Max retries exceeded with url: / (Caused by ConnectTimeoutError(<urllib3.connection.HTTPConnection object at 0x106418b38>, 'Connection to codeforces.com timed out. (connect timeout=7)'))

During handling of the above exception, another exception occurred:

Traceback (most recent call last):
  File "/Users/feifei/workspace/VirtualJudge/venv/lib/python3.7/site-packages/spider-1.0-py3.7.egg/spider/utils.py", line 48, in get
    self._response = self._request.get(url, timeout=self._timeout, proxies=self._proxies, **kwargs)
  File "/Users/feifei/workspace/VirtualJudge/venv/lib/python3.7/site-packages/requests/sessions.py", line 537, in get
    return self.request('GET', url, **kwargs)
  File "/Users/feifei/workspace/VirtualJudge/venv/lib/python3.7/site-packages/requests/sessions.py", line 524, in request
    resp = self.send(prep, **send_kwargs)
  File "/Users/feifei/workspace/VirtualJudge/venv/lib/python3.7/site-packages/raven/breadcrumbs.py", line 341, in send
    resp = real_send(self, request, *args, **kwargs)
  File "/Users/feifei/workspace/VirtualJudge/venv/lib/python3.7/site-packages/requests/sessions.py", line 637, in send
    r = adapter.send(request, **kwargs)
  File "/Users/feifei/workspace/VirtualJudge/venv/lib/python3.7/site-packages/requests/adapters.py", line 504, in send
    raise ConnectTimeout(e, request=request)
requests.exceptions.ConnectTimeout: HTTPConnectionPool(host='codeforces.com', port=80): Max retries exceeded with url: / (Caused by ConnectTimeoutError(<urllib3.connection.HTTPConnection object at 0x106418b38>, 'Connection to codeforces.com timed out. (connect timeout=7)'))
2018-12-28 10:44:33,711 ERROR HTTPConnectionPool(host='codeforces.com', port=80): Max retries exceeded with url: / (Caused by ConnectTimeoutError(<urllib3.connection.HTTPConnection object at 0x107604d68>, 'Connection to codeforces.com timed out. (connect timeout=7)'))
Traceback (most recent call last):
  File "/Users/feifei/workspace/VirtualJudge/venv/lib/python3.7/site-packages/urllib3/connection.py", line 159, in _new_conn
    (self._dns_host, self.port), self.timeout, **extra_kw)
  File "/Users/feifei/workspace/VirtualJudge/venv/lib/python3.7/site-packages/urllib3/util/connection.py", line 80, in create_connection
    raise err
  File "/Users/feifei/workspace/VirtualJudge/venv/lib/python3.7/site-packages/urllib3/util/connection.py", line 70, in create_connection
    sock.connect(sa)
socket.timeout: timed out

During handling of the above exception, another exception occurred:

Traceback (most recent call last):
  File "/Users/feifei/workspace/VirtualJudge/venv/lib/python3.7/site-packages/urllib3/connectionpool.py", line 600, in urlopen
    chunked=chunked)
  File "/Users/feifei/workspace/VirtualJudge/venv/lib/python3.7/site-packages/urllib3/connectionpool.py", line 354, in _make_request
    conn.request(method, url, **httplib_request_kw)
  File "/usr/local/Cellar/python/3.7.0/Frameworks/Python.framework/Versions/3.7/lib/python3.7/http/client.py", line 1229, in request
    self._send_request(method, url, body, headers, encode_chunked)
  File "/usr/local/Cellar/python/3.7.0/Frameworks/Python.framework/Versions/3.7/lib/python3.7/http/client.py", line 1275, in _send_request
    self.endheaders(body, encode_chunked=encode_chunked)
  File "/usr/local/Cellar/python/3.7.0/Frameworks/Python.framework/Versions/3.7/lib/python3.7/http/client.py", line 1224, in endheaders
    self._send_output(message_body, encode_chunked=encode_chunked)
  File "/usr/local/Cellar/python/3.7.0/Frameworks/Python.framework/Versions/3.7/lib/python3.7/http/client.py", line 1016, in _send_output
    self.send(msg)
  File "/usr/local/Cellar/python/3.7.0/Frameworks/Python.framework/Versions/3.7/lib/python3.7/http/client.py", line 956, in send
    self.connect()
  File "/Users/feifei/workspace/VirtualJudge/venv/lib/python3.7/site-packages/urllib3/connection.py", line 181, in connect
    conn = self._new_conn()
  File "/Users/feifei/workspace/VirtualJudge/venv/lib/python3.7/site-packages/urllib3/connection.py", line 164, in _new_conn
    (self.host, self.timeout))
urllib3.exceptions.ConnectTimeoutError: (<urllib3.connection.HTTPConnection object at 0x107604d68>, 'Connection to codeforces.com timed out. (connect timeout=7)')

During handling of the above exception, another exception occurred:

Traceback (most recent call last):
  File "/Users/feifei/workspace/VirtualJudge/venv/lib/python3.7/site-packages/requests/adapters.py", line 449, in send
    timeout=timeout
  File "/Users/feifei/workspace/VirtualJudge/venv/lib/python3.7/site-packages/urllib3/connectionpool.py", line 638, in urlopen
    _stacktrace=sys.exc_info()[2])
  File "/Users/feifei/workspace/VirtualJudge/venv/lib/python3.7/site-packages/urllib3/util/retry.py", line 398, in increment
    raise MaxRetryError(_pool, url, error or ResponseError(cause))
urllib3.exceptions.MaxRetryError: HTTPConnectionPool(host='codeforces.com', port=80): Max retries exceeded with url: / (Caused by ConnectTimeoutError(<urllib3.connection.HTTPConnection object at 0x107604d68>, 'Connection to codeforces.com timed out. (connect timeout=7)'))

During handling of the above exception, another exception occurred:

Traceback (most recent call last):
  File "/Users/feifei/workspace/VirtualJudge/venv/lib/python3.7/site-packages/spider-1.0-py3.7.egg/spider/utils.py", line 48, in get
    self._response = self._request.get(url, timeout=self._timeout, proxies=self._proxies, **kwargs)
  File "/Users/feifei/workspace/VirtualJudge/venv/lib/python3.7/site-packages/requests/sessions.py", line 537, in get
    return self.request('GET', url, **kwargs)
  File "/Users/feifei/workspace/VirtualJudge/venv/lib/python3.7/site-packages/requests/sessions.py", line 524, in request
    resp = self.send(prep, **send_kwargs)
  File "/Users/feifei/workspace/VirtualJudge/venv/lib/python3.7/site-packages/raven/breadcrumbs.py", line 341, in send
    resp = real_send(self, request, *args, **kwargs)
  File "/Users/feifei/workspace/VirtualJudge/venv/lib/python3.7/site-packages/requests/sessions.py", line 637, in send
    r = adapter.send(request, **kwargs)
  File "/Users/feifei/workspace/VirtualJudge/venv/lib/python3.7/site-packages/requests/adapters.py", line 504, in send
    raise ConnectTimeout(e, request=request)
requests.exceptions.ConnectTimeout: HTTPConnectionPool(host='codeforces.com', port=80): Max retries exceeded with url: / (Caused by ConnectTimeoutError(<urllib3.connection.HTTPConnection object at 0x107604d68>, 'Connection to codeforces.com timed out. (connect timeout=7)'))
